Workbook

Sheet 안내
A1: 안내ID | B1: 시트명 | C1: 용도 | D1: 누가 주로 사용하나 | E1: 설명
A2: INFO-001 | B2: 현원_원본 | C2: 원본보관 | D2: 관리자 | E2: 샘플 원본 그대로 보관
A3: INFO-002 | B3: 반별학생명단 | C3: 보기용 | D3: 실무자 | E3: 반 안에 어떤 학생이 있는지 확인
A4: INFO-003 | B4: 학생목록 | C4: 기준정보 | D4: 관리자 | E4: 학생 검색용 기준 목록
A5: INFO-004 | B5: 반마스터 | C5: 기준정보 | D5: 관리자 | E5: 반명=교재 기준. 수업/피드백 2종 관리
A6: INFO-005 | B6: 학생반배정 | C6: 기준정보 | D6: 관리자 | E6: 학생-반 소속 관계. 반이동 시 여기 수정
A7: INFO-006 | B7: 교재재고 | C7: 핵심 | D7: 실무자/관리자 | E7: 초기재고 입력, 누적배부/현재재고 자동집계
A8: INFO-007 | B8: 일괄배부입력 | C8: 핵심입력 | D8: 실무자 | E8: 매월 반별 교재 일괄배부 입력
A9: INFO-008 | B9: 개별배부입력 | C9: 핵심입력 | D9: 실무자 | E9: 특정 학생만 추가 배부 입력
A10: INFO-009 | B10: 배부로그 | C10: 기록 | D10: 자동/AppSheet | E10: 모든 배부 기록 저장
A11: INFO-010 | B11: 학생조회 | C11: 조회 | D11: 실무자 | E11: 학생명+기준일로 과거 배부내역 확인
A12: INFO-011 | B12: 특이사항모아보기 | C12: 조회 | D12: 실무자 | E12: 특이사항 있는 학생만 한 번에 확인
... A14: INFO-013 | B14: AppSheet_설정 | C14: 설정 | D14: 관리자 | E14: AppSheet 연결/액션 만들기 가이드

Sheet 현원_원본
A1: 현원
A3: Data DownLoad 일자 : 2026-03-25
A5: 반명 | B5: 학생명
A6: (목) 301호 생명D 강원휘(13시20분) | B6: (5)강연웅2804
A7: (목) 501호 언매 김종훈(08시) | B7: (5)강연웅2804
A8: (화) 303호 지학D 이병훈(08시) | B8: (5)강연웅2804
A9: 정규(수)802B 국어 김종훈 | B9: (5)강연웅2804
A10: 정규(월금)801B 미적 전종현(수매Q) | B10: (5)강연웅2804
A11: 정규(토)901A 영어 김희준 | B11: (5)강연웅2804
A12: (목) 702호 화작 조영신(13시20분) | B12: (5)강유찬8685
A13: (목) 별관지하 세지A 이승국(08시) | B13: (5)강유찬8685
A14: (화) 별관302호 사문B 강성욱(13시20분) | B14: (5)강유찬8685
A15: 정규(수)701A 영어 김희준 | B15: (5)강유찬8685
A16: 정규(월금)603B 미적 김학림(수매T) | B16: (5)강유찬8685
... A3934: 정규(월)403B 영어 지종규 | B3934: 황준서0113

Sheet 학생목록
A1: 학생명 | B1: 현재배정반수
A2: =IFERROR(__xludf.DUMMYFUNCTION("SORT( UNIQUE( FILTER( TRIM('학생반배정'!B2:B1000), TRIM('학생반배정'!B2:B1000)<>"""", TRIM('학생반배정'!D2:D1000)=""재원"" ) ) )"),"(5)강연웅2804") -> (5)강연웅2804 | B2: {=IF( A2:A1000<>"", COUNTIFS('학생반배정'!B:B, A2:A1000, '학생반배정'!D:D, "재원"), "" )} -> 16
A3: =IFERROR(__xludf.DUMMYFUNCTION("""COMPUTED_VALUE"""),"(5)강유찬8685") -> (5)강유찬8685 | B3: 14
A4: =IFERROR(__xludf.DUMMYFUNCTION("""COMPUTED_VALUE"""),"(5)고강민8799") -> (5)고강민8799 | B4: 16
A5: =IFERROR(__xludf.DUMMYFUNCTION("""COMPUTED_VALUE"""),"(5)김준수3824") -> (5)김준수3824 | B5: 16
A6: =IFERROR(__xludf.DUMMYFUNCTION("""COMPUTED_VALUE"""),"(5)김진혁7053") -> (5)김진혁7053 | B6: 16
A7: =IFERROR(__xludf.DUMMYFUNCTION("""COMPUTED_VALUE"""),"(5)문혁기2222") -> (5)문혁기2222 | B7: 16
A8: =IFERROR(__xludf.DUMMYFUNCTION("""COMPUTED_VALUE"""),"(5)박경동8420") -> (5)박경동8420 | B8: 16
A9: =IFERROR(__xludf.DUMMYFUNCTION("""COMPUTED_VALUE"""),"(5)방준혁8763") -> (5)방준혁8763 | B9: 16
A10: =IFERROR(__xludf.DUMMYFUNCTION("""COMPUTED_VALUE"""),"(5)손찬우7814") -> (5)손찬우7814 | B10: 16
A11: =IFERROR(__xludf.DUMMYFUNCTION("""COMPUTED_VALUE"""),"(5)신희건2420") -> (5)신희건2420 | B11: 13
A12: =IFERROR(__xludf.DUMMYFUNCTION("""COMPUTED_VALUE"""),"(5)오승민8884") -> (5)오승민8884 | B12: 16
A13: =IFERROR(__xludf.DUMMYFUNCTION("""COMPUTED_VALUE"""),"(5)유민재7079") -> (5)유민재7079 | B13: 16
A14: =IFERROR(__xludf.DUMMYFUNCTION("""COMPUTED_VALUE"""),"(5)윤태웅1592") -> (5)윤태웅1592 | B14: 16
A15: =IFERROR(__xludf.DUMMYFUNCTION("""COMPUTED_VALUE"""),"(5)이민욱7522") -> (5)이민욱7522 | B15: 16
A16: =IFERROR(__xludf.DUMMYFUNCTION("""COMPUTED_VALUE"""),"(5)이영욱6966") -> (5)이영욱6966 | B16: 16
A17: =IFERROR(__xludf.DUMMYFUNCTION("""COMPUTED_VALUE"""),"(5)이재국9609") -> (5)이재국9609 | B17: 16
A18: =IFERROR(__xludf.DUMMYFUNCTION("""COMPUTED_VALUE"""),"(5)조준범0784") -> (5)조준범0784 | B18: 16
A19: =IFERROR(__xludf.DUMMYFUNCTION("""COMPUTED_VALUE"""),"(5)지무경1270") -> (5)지무경1270 | B19: 16
A20: =IFERROR(__xludf.DUMMYFUNCTION("""COMPUTED_VALUE"""),"(5)최민준4523") -> (5)최민준4523 | B20: 16
A21: =IFERROR(__xludf.DUMMYFUNCTION("""COMPUTED_VALUE"""),"(5)하시원2339") -> (5)하시원2339 | B21: 16
A22: =IFERROR(__xludf.DUMMYFUNCTION("""COMPUTED_VALUE"""),"(강)기영윤7318") -> (강)기영윤7318 | B22: 16
A23: =IFERROR(__xludf.DUMMYFUNCTION("""COMPUTED_VALUE"""),"(강)김도형7747") -> (강)김도형7747 | B23: 14
A24: =IFERROR(__xludf.DUMMYFUNCTION("""COMPUTED_VALUE"""),"(강)김민건8182") -> (강)김민건8182 | B24: 16
A25: =IFERROR(__xludf.DUMMYFUNCTION("""COMPUTED_VALUE"""),"(강)김수홍7778") -> (강)김수홍7778 | B25: 16
A26: =IFERROR(__xludf.DUMMYFUNCTION("""COMPUTED_VALUE"""),"(강)민준혁9223") -> (강)민준혁9223 | B26: 16
A27: =IFERROR(__xludf.DUMMYFUNCTION("""COMPUTED_VALUE"""),"(강)박성효3234") -> (강)박성효3234 | B27: 16
A28: =IFERROR(__xludf.DUMMYFUNCTION("""COMPUTED_VALUE"""),"(강)박주석8032") -> (강)박주석8032 | B28: 16
A29: =IFERROR(__xludf.DUMMYFUNCTION("""COMPUTED_VALUE"""),"(강)왕효준2880") -> (강)왕효준2880 | B29: 15
A30: =IFERROR(__xludf.DUMMYFUNCTION("""COMPUTED_VALUE"""),"(강)이도현1102") -> (강)이도현1102 | B30: 16
A31: =IFERROR(__xludf.DUMMYFUNCTION("""COMPUTED_VALUE"""),"(강)이동건5693") -> (강)이동건5693 | B31: 16
A32: =IFERROR(__xludf.DUMMYFUNCTION("""COMPUTED_VALUE"""),"(강)장윤건7351") -> (강)장윤건7351 | B32: 16
A33: =IFERROR(__xludf.DUMMYFUNCTION("""COMPUTED_VALUE"""),"(개_5)김민준5243") -> (개_5)김민준5243 | B33: 16
A34: =IFERROR(__xludf.DUMMYFUNCTION("""COMPUTED_VALUE"""),"(개_5)민정원9707") -> (개_5)민정원9707 | B34: 16
A35: =IFERROR(__xludf.DUMMYFUNCTION("""COMPUTED_VALUE"""),"(개_5)박상현0208") -> (개_5)박상현0208 | B35: 16
A36: =IFERROR(__xludf.DUMMYFUNCTION("""COMPUTED_VALUE"""),"(개_5)박시우7232") -> (개_5)박시우7232 | B36: 16
A37: =IFERROR(__xludf.DUMMYFUNCTION("""COMPUTED_VALUE"""),"(개_5)방승수0714") -> (개_5)방승수0714 | B37: 16
A38: =IFERROR(__xludf.DUMMYFUNCTION("""COMPUTED_VALUE"""),"(개_5)서은후1353") -> (개_5)서은후1353 | B38: 16
A39: =IFERROR(__xludf.DUMMYFUNCTION("""COMPUTED_VALUE"""),"(개_5)이한결0479") -> (개_5)이한결0479 | B39: 16
A40: =IFERROR(__xludf.DUMMYFUNCTION("""COMPUTED_VALUE"""),"(개_5)임건우5242") -> (개_5)임건우5242 | B40: 16
...

Sheet 일괄배부입력
A1: 요청ID | B1: 배부일 | C1: 반명 | D1: 배부장소 | E1: 학생당수량 | F1: 총대상학생수 | G1: 총배부수량 | H1: 실행상태 | I1: 담당자 | J1: 메모
A2: BULK-0001 | E2: 1 | F2: =COUNTIF('학생반배정'!$C:$C,C2) -> 0 | G2: =E2*F2 -> 0 | H2: 입력
A3: BULK-0002 | E3: 1 | F3: =COUNTIF('학생반배정'!$C:$C,C3) -> 0 | G3: =E3*F3 -> 0 | H3: 입력
A4: BULK-0003 | E4: 1 | F4: =COUNTIF('학생반배정'!$C:$C,C4) -> 0 | G4: =E4*F4 -> 0 | H4: 입력
A5: BULK-0004 | E5: 1 | F5: =COUNTIF('학생반배정'!$C:$C,C5) -> 0 | G5: =E5*F5 -> 0 | H5: 입력
A6: BULK-0005 | E6: 1 | F6: =COUNTIF('학생반배정'!$C:$C,C6) -> 0 | G6: =E6*F6 -> 0 | H6: 입력
A7: BULK-0006 | E7: 1 | F7: =COUNTIF('학생반배정'!$C:$C,C7) -> 0 | G7: =E7*F7 -> 0 | H7: 입력
A8: BULK-0007 | E8: 1 | F8: =COUNTIF('학생반배정'!$C:$C,C8) -> 0 | G8: =E8*F8 -> 0 | H8: 입력
A9: BULK-0008 | E9: 1 | F9: =COUNTIF('학생반배정'!$C:$C,C9) -> 0 | G9: =E9*F9 -> 0 | H9: 입력
A10: BULK-0009 | E10: 1 | F10: =COUNTIF('학생반배정'!$C:$C,C10) -> 0 | G10: =E10*F10 -> 0 | H10: 입력
A11: BULK-0010 | E11: 1 | F11: =COUNTIF('학생반배정'!$C:$C,C11) -> 0 | G11: =E11*F11 -> 0 | H11: 입력
A12: BULK-0011 | E12: 1 | F12: =COUNTIF('학생반배정'!$C:$C,C12) -> 0 | G12: =E12*F12 -> 0 | H12: 입력
A13: BULK-0012 | E13: 1 | F13: =COUNTIF('학생반배정'!$C:$C,C13) -> 0 | G13: =E13*F13 -> 0 | H13: 입력
... A51: BULK-0050 | E51: 1 | F51: =COUNTIF('학생반배정'!$C:$C,C51) -> 0 | G51: =E51*F51 -> 0 | H51: 입력
A52: 925f6c41 | C52: (목) 301호 생명D 강원휘(13시20분) | E52: 1 | F52: =COUNTIF('학생반배정'!$C:$C,C52) -> 0 | G52: =E52*F52 -> 0
A53: 9041d187 | C53: (목) 301호 생명D 강원휘(13시20분) | E53: 1 | F53: =COUNTIF('학생반배정'!$C:$C,C53) -> 0 | G53: =E53*F53 -> 0
A54: c32265da | C54: (화) 702호 화작 임현호(09시20분) | E54: 1 | F54: =COUNTIF('학생반배정'!$C:$C,C54) -> 0 | G54: =E54*F54 -> 0
A55: 0d97b756 | C55: 정규(토)801B 영어 김희준 | E55: 1 | F55: =COUNTIF('학생반배정'!$C:$C,C55) -> 0 | G55: =E55*F55 -> 0
A56: ac779614 | C56: (목) 301호 생명C 강원휘(08시) | E56: 1 | F56: =COUNTIF('학생반배정'!$C:$C,C56) -> 0 | G56: =E56*F56 -> 0
A57: 85a3d91e | C57: (목) 301호 생명C 강원휘(08시) | E57: 1 | F57: =COUNTIF('학생반배정'!$C:$C,C57) -> 0 | G57: =E57*F57 -> 0
A58: 114123b8 | C58: (목) 301호 생명C 강원휘(08시) | E58: 1 | F58: =COUNTIF('학생반배정'!$C:$C,C58) -> 0 | G58: =E58*F58 -> 0
A59: ebbe7ceb | C59: 정규(수)702A 국어 백종수 | E59: 1 | F59: =COUNTIF('학생반배정'!$C:$C,C59) -> 0 | G59: =E59*F59 -> 0
A60: fb506369 | C60: (목) 302호 지학B 장병선(08시) | E60: 1 | F60: =COUNTIF('학생반배정'!$C:$C,C60) -> 0 | G60: =E60*F60 -> 0
A61: 37632d1a | E61: 1 | F61: =COUNTIF('학생반배정'!$C:$C,C61) -> 0 | G61: =E61*F61 -> 0
A62: dabed81c | C62: (목) 403호 동사 신인섭(08시) | E62: 1 | F62: =COUNTIF('학생반배정'!$C:$C,C62) -> 0 | G62: =E62*F62 -> 0
A63: f9751b90 | B63: 46104 | C63: (목) 301호 생명D 강원휘(13시20분) | D63: 4층지원실 | E63: 1 | F63: =COUNTIF('학생반배정'!$C:$C,C63) -> 0 | G63: =E63*F63 -> 0
A64: 9a61eaaf | B64: 46107 | C64: (목) 703호 화작 임현호(08시) | D64: 창고 | E64: 1 | F64: =COUNTIF('학생반배정'!$C:$C,C64) -> 0 | G64: =E64*F64 -> 0
A65: 7cd24e6d | B65: 46107 | C65: (목) 703호 화작 김종훈(09시20분) | D65: 4층지원실 | E65: 1 | F65: =COUNTIF('학생반배정'!$C:$C,C65) -> 0 | G65: =E65*F65 -> 0
A66: f80d5c02 | B66: 46109 | C66: (목) 별관지하 세지A 이승국(08시) | D66: 창고 | E66: 1 | F66: =COUNTIF('학생반배정'!$C:$C,C66) -> 0 | G66: =E66*F66 -> 0
A67: 3689c8c8 | B67: 46107 | C67: (화) 301호 생명B 강원휘(13시20분) | D67: 창고 | E67: 1 | F67: =COUNTIF('학생반배정'!$C:$C,C67) -> 0 | G67: =E67*F67 -> 0
A68: 3e8d482a | B68: 46107 | C68: (화) 301호 생명B 강원휘(13시20분) | D68: 창고 | E68: 1 | F68: =COUNTIF('학생반배정'!$C:$C,C68) -> 0 | G68: =E68*F68 -> 0
A69: 0ddc0de3 | B69: 46112 | C69: (목) 302호 지학B 장병선(08시) | D69: 창고 | E69: 1 | F69: =COUNTIF('학생반배정'!$C:$C,C69) -> 0 | G69: =E69*F69 -> 0
A70: be289ba0 | B70: 46114 | C70: 국매깨 2-5 | D70: 창고 | E70: 1 | F70: =COUNTIF('학생반배정'!$C:$C,C70) -> 0 | G70: =E70*F70 -> 0
A71: 1a52f941 | B71: 46114 | C71: 국매깨 2-5 | D71: 창고 | E71: 1 | F71: =COUNTIF('학생반배정'!$C:$C,C71) -> 0 | G71: =E71*F71 -> 0
A72: 48af2596 | B72: 46114 | C72: 국매깨 2-5 | D72: 창고 | E72: 1 | F72: =COUNTIF('학생반배정'!$C:$C,C72) -> 0 | G72: =E72*F72 -> 0
A73: 81632263 | B73: 46114 | C73: 국매깨 2-5 | D73: 창고 | E73: 1 | F73: =COUNTIF('학생반배정'!$C:$C,C73) -> 0 | G73: =E73*F73 -> 0
A74: 71a70a33 | B74: 46114 | C74: 국매깨 2-6 | D74: 창고 | E74: 1 | F74: =COUNTIF('학생반배정'!$C:$C,C74) -> 0 | G74: =E74*F74 -> 0
... A85: c8acbe28 | B85: 46119 | C85: TEST 교재1 | D85: 창고 | E85: 1 | F85: =COUNTIF('학생반배정'!$C:$C,C85) -> 4 | G85: =E85*F85 -> 4
A86: ea8fa128 | B86: 46121 | C86: TEST 교재1 | D86: 창고 | E86: 1 | F86: 4 | G86: 4
A87: d8e8e420 | B87: 46121 | C87: TEST 교재1 | D87: 창고 | E87: 1 | F87: =COUNTIF('학생반배정'!$C:$C,C87) -> 4 | G87: =E87*F87 -> 4
...

Sheet 장소마스터
A1: 장소명
A2: 창고
A3: 4층지원실
A4: 8층지원실

Sheet 개별배부입력
A1: 요청ID | B1: 배부일 | C1: 학생명 | D1: 배부반 | E1: 배부장소 | F1: 현재반 | G1: 수량 | H1: 특이사항여부 | I1: 특이사항유형 | J1: 특이사항내용 | K1: 담당자
A2: IND-0001 | G2: 1 | H2: N
A3: IND-0002 | G3: 1 | H3: N
A4: IND-0003 | G4: 1 | H4: N
A5: IND-0004 | G5: 1 | H5: N
A6: IND-0005 | G6: 1 | H6: N
A7: IND-0006 | G7: 1 | H7: N
A8: IND-0007 | G8: 1 | H8: N
A9: IND-0008 | G9: 1 | H9: N
A10: IND-0009 | G10: 1 | H10: N
A11: IND-0010 | G11: 1 | H11: N
A12: IND-0011 | G12: 1 | H12: N
A13: IND-0012 | G13: 1 | H13: N
... A101: IND-0100 | G101: 1 | H101: N
A102: 4a9a6a16 | B102: 46106 | C102: (개_일)김유진2847 | F102: (목) 502호 사문E 장진민(13시20분) | G102: 1 | H102: Y | I102: 추가지급 | J102: 반변경 | K102: 김지유
A103: 2cf47c6d | B103: 46103 | C103: (선5)이재선5347 | D103: (화) 302호 지학A 장병선(08시) | F103: (목) 502호 사문E 장진민(13시20분) | G103: 1 | H103: Y | I103: 분실
A104: 94421a0e | B104: 46106 | C104: (선5)이재선5347 | D104: (목) 502호 사문D 장진민(08시) | F104: (목) 502호 사문E 장진민(13시20분) | G104: 1 | H104: N
A105: 2b7683ea | B105: 46106 | C105: (선5)이재선5347 | D105: (목) 501호 언매 임현호(13시20분) | F105: (목) 301호 생명D 강원휘(13시20분) | G105: 1 | H105: Y | I105: 재배부
A106: 069b5d32 | B106: 46106 | C106: 문아라4000 | F106: (목) 301호 생명D 강원휘(13시20분) | G106: 1 | H106: Y | I106: 반이동후추가지급
A107: 046322dc | B107: 46106 | C107: 문아라4000 | D107: (화) 별관302호 사문B 강성욱(13시20분) | F107: (목) 301호 생명D 강원휘(13시20분) | G107: 1 | H107: N
A108: fa41e16c | B108: 46106 | C108: (선5)이재선5347 | D108: (화) 302호 지학A 장병선(08시) | F108: (목) 301호 생명D 강원휘(13시20분) | G108: 1 | H108: Y | I108: 분실
A109: 7413f435 | B109: 46106 | C109: 문아라4000 | D109: (목) 501호 언매 김종훈(08시) | F109: (목) 301호 생명D 강원휘(13시20분) | G109: 1 | H109: N
A110: f6ba729b | B110: 46106 | C110: 문아라4000 | D110: (목) 501호 언매 김종훈(08시) | F110: (목) 301호 생명D 강원휘(13시20분) | G110: 1 | H110: Y | I110: 오배부
A111: 8b12d83a | B111: 46106 | C111: 문아라4000 | D111: (목) 별관201 생윤E 한진구(13시20분) | F111: (목) 301호 생명D 강원휘(13시20분) | G111: 1 | H111: Y | I111: 분실
A112: fb0363ac | B112: 46106 | C112: 문아라4000 | D112: 정규(월금)703B 확통 이민호B(수매M) | F112: (목) 301호 생명D 강원휘(13시20분) | G112: 1 | H112: Y | I112: 분실
A113: a0643500 | B113: 46105 | C113: (선5)장은수1716 | D113: (목) 702호 화작 백종수(09시20분) | F113: (목) 301호 생명D 강원휘(13시20분) | G113: 1 | H113: N
A114: 42a056cb | B114: 46099 | C114: 김정환6242 | D114: 정규(월금)801B 미적 전종현(수매Q) | F114: (목) 301호 생명D 강원휘(13시20분) | G114: 1 | H114: N
A115: 56feaf66 | B115: 46101 | C115: 김정환6242 | F115: (목) 301호 생명D 강원휘(13시20분) | G115: 1 | H115: Y | I115: 추가지급
A116: b4b87259 | B116: 46107 | C116: 문아라4000 | D116: (목) 501호 언매 김종훈(08시) | F116: (목) 301호 생명D 강원휘(13시20분) | G116: 1 | H116: Y | I116: 분실 | K116: 김지유
A117: 9b9194d3 | B117: 46107 | C117: 문아라4000 | D117: 정규(수)902A 국어 김종훈 | F117: (목) 301호 생명D 강원휘(13시20분) | G117: 1 | H117: Y | I117: 분실 | J117: 분실 | K117: 김지유
A118: 5c7bbd49 | B118: 46113 | C118: 문아라4000 | D118: (목) 501호 언매 김종훈(08시) | F118: (목) 301호 생명D 강원휘(13시20분) | G118: 1 | H118: Y | I118: 오배부
A119: 6d5ad127 | B119: 46107 | C119: (5)강연웅2804 | D119: (목) 301호 생명D 강원휘(13시20분) | E119: 창고 | F119: (목) 301호 생명D 강원휘(13시20분) | G119: 1 | H119: Y | I119: 추가지급 | K119: 김지유
A120: 0aadd816 | B120: 46107 | C120: (5)강연웅2804 | D120: (목) 501호 언매 김종훈(08시) | E120: 창고 | F120: (목) 301호 생명D 강원휘(13시20분) | G120: 1 | H120: Y | I120: 재배부 | K120: ㅇㅇㅇ
A121: be67aa9d | B121: 46083 | C121: (5)강연웅2804 | D121: (목) 301호 생명D 강원휘(13시20분) | E121: 창고 | F121: (목) 301호 생명D 강원휘(13시20분) | G121: 1 | H121: Y | I121: 분실 | K121: 김지유
A122: a3aabd16 | B122: 46107 | C122: 김민서2753 | D122: (목) 501호 언매 임현호(13시20분) | E122: 창고 | F122: (목) 301호 생명D 강원휘(13시20분) | G122: 1 | H122: Y | I122: 분실 | K122: 김대열
A123: b9080dab | B123: 46100 | C123: (개_5)김민준5243 | D123: (목) 303호 정법 강성욱(13시20분) | E123: 창고 | F123: (목) 301호 생명D 강원휘(13시20분) | G123: 1 | H123: Y | I123: 분실 | K123: 최연순
A124: 43ea4f17 | B124: 46107 | C124: (5)고강민8799 | D124: 정규(월금)701A 미적 이민호A(수매Q) | E124: 4층지원실 | F124: (목) 301호 생명D 강원휘(13시20분) | G124: 1 | H124: Y | I124: 재배부 | K124: 2
A125: 227c72fd | B125: 46114 | C125: (5)강연웅2804 | D125: 국매깨 2-5 | E125: 4층지원실 | F125: 국매깨 2-5 | G125: 1 | H125: Y | I125: 기타 | J125: 오후등원 | K125: 엄선훈
A126: 74695eab | B126: 46114 | C126: (5)강유찬8685 | D126: 정규(월금)603B 미적 김학림(수매T) | E126: 창고 | F126: 정규(월금)603B 미적 김학림(수매T) | G126: 1 | H126: Y | I126: 기타 | J126: ㅁㅇㄹ | K126: ㅇㅅㅎ
A127: 6c56ce4e | B127: 46114 | C127: 강태우7482 | D127: 수매깨 Q 1-1 | E127: 창고 | F127: 수매깨 Q 1-1 | G127: 1 | H127: Y | I127: 분실 | J127: 분실 | K127: 엄선훈
...

Sheet 재원학생목록
A1: 학생id | B1: 학생명
A2: {=IF(B2:B2432<>"","STU-"&TEXT(ROW(B2:B2432),"0000"),"")} -> STU-0002 | B2: =IFERROR(__xludf.DUMMYFUNCTION("SORT(UNIQUE(FILTER('학생반배정'!B2:B2432,'학생반배정'!D2:D2432=""재원"",'학생반배정'!B2:B2432<>"""")))"),"(5)강연웅2804") -> (5)강연웅2804
A3: STU-0003 | B3: =IFERROR(__xludf.DUMMYFUNCTION("""COMPUTED_VALUE"""),"(5)강유찬8685") -> (5)강유찬8685
A4: STU-0004 | B4: =IFERROR(__xludf.DUMMYFUNCTION("""COMPUTED_VALUE"""),"(5)고강민8799") -> (5)고강민8799
A5: STU-0005 | B5: =IFERROR(__xludf.DUMMYFUNCTION("""COMPUTED_VALUE"""),"(5)김준수3824") -> (5)김준수3824
A6: STU-0006 | B6: =IFERROR(__xludf.DUMMYFUNCTION("""COMPUTED_VALUE"""),"(5)김진혁7053") -> (5)김진혁7053
A7: STU-0007 | B7: =IFERROR(__xludf.DUMMYFUNCTION("""COMPUTED_VALUE"""),"(5)문혁기2222") -> (5)문혁기2222
A8: STU-0008 | B8: =IFERROR(__xludf.DUMMYFUNCTION("""COMPUTED_VALUE"""),"(5)박경동8420") -> (5)박경동8420
A9: STU-0009 | B9: =IFERROR(__xludf.DUMMYFUNCTION("""COMPUTED_VALUE"""),"(5)방준혁8763") -> (5)방준혁8763
A10: STU-0010 | B10: =IFERROR(__xludf.DUMMYFUNCTION("""COMPUTED_VALUE"""),"(5)손찬우7814") -> (5)손찬우7814
A11: STU-0011 | B11: =IFERROR(__xludf.DUMMYFUNCTION("""COMPUTED_VALUE"""),"(5)신희건2420") -> (5)신희건2420
A12: STU-0012 | B12: =IFERROR(__xludf.DUMMYFUNCTION("""COMPUTED_VALUE"""),"(5)오승민8884") -> (5)오승민8884
A13: STU-0013 | B13: =IFERROR(__xludf.DUMMYFUNCTION("""COMPUTED_VALUE"""),"(5)유민재7079") -> (5)유민재7079
A14: STU-0014 | B14: =IFERROR(__xludf.DUMMYFUNCTION("""COMPUTED_VALUE"""),"(5)윤태웅1592") -> (5)윤태웅1592
A15: STU-0015 | B15: =IFERROR(__xludf.DUMMYFUNCTION("""COMPUTED_VALUE"""),"(5)이민욱7522") -> (5)이민욱7522
A16: STU-0016 | B16: =IFERROR(__xludf.DUMMYFUNCTION("""COMPUTED_VALUE"""),"(5)이영욱6966") -> (5)이영욱6966
A17: STU-0017 | B17: =IFERROR(__xludf.DUMMYFUNCTION("""COMPUTED_VALUE"""),"(5)이재국9609") -> (5)이재국9609
A18: STU-0018 | B18: =IFERROR(__xludf.DUMMYFUNCTION("""COMPUTED_VALUE"""),"(5)조준범0784") -> (5)조준범0784
A19: STU-0019 | B19: =IFERROR(__xludf.DUMMYFUNCTION("""COMPUTED_VALUE"""),"(5)지무경1270") -> (5)지무경1270
A20: STU-0020 | B20: =IFERROR(__xludf.DUMMYFUNCTION("""COMPUTED_VALUE"""),"(5)최민준4523") -> (5)최민준4523
A21: STU-0021 | B21: =IFERROR(__xludf.DUMMYFUNCTION("""COMPUTED_VALUE"""),"(5)하시원2339") -> (5)하시원2339
A22: STU-0022 | B22: =IFERROR(__xludf.DUMMYFUNCTION("""COMPUTED_VALUE"""),"(강)기영윤7318") -> (강)기영윤7318
A23: STU-0023 | B23: =IFERROR(__xludf.DUMMYFUNCTION("""COMPUTED_VALUE"""),"(강)김도형7747") -> (강)김도형7747
A24: STU-0024 | B24: =IFERROR(__xludf.DUMMYFUNCTION("""COMPUTED_VALUE"""),"(강)김민건8182") -> (강)김민건8182
A25: STU-0025 | B25: =IFERROR(__xludf.DUMMYFUNCTION("""COMPUTED_VALUE"""),"(강)김수홍7778") -> (강)김수홍7778
A26: STU-0026 | B26: =IFERROR(__xludf.DUMMYFUNCTION("""COMPUTED_VALUE"""),"(강)민준혁9223") -> (강)민준혁9223
A27: STU-0027 | B27: =IFERROR(__xludf.DUMMYFUNCTION("""COMPUTED_VALUE"""),"(강)박성효3234") -> (강)박성효3234
A28: STU-0028 | B28: =IFERROR(__xludf.DUMMYFUNCTION("""COMPUTED_VALUE"""),"(강)박주석8032") -> (강)박주석8032
A29: STU-0029 | B29: =IFERROR(__xludf.DUMMYFUNCTION("""COMPUTED_VALUE"""),"(강)왕효준2880") -> (강)왕효준2880
A30: STU-0030 | B30: =IFERROR(__xludf.DUMMYFUNCTION("""COMPUTED_VALUE"""),"(강)이도현1102") -> (강)이도현1102
A31: STU-0031 | B31: =IFERROR(__xludf.DUMMYFUNCTION("""COMPUTED_VALUE"""),"(강)이동건5693") -> (강)이동건5693
A32: STU-0032 | B32: =IFERROR(__xludf.DUMMYFUNCTION("""COMPUTED_VALUE"""),"(강)장윤건7351") -> (강)장윤건7351
A33: STU-0033 | B33: =IFERROR(__xludf.DUMMYFUNCTION("""COMPUTED_VALUE"""),"(개_5)김민준5243") -> (개_5)김민준5243
A34: STU-0034 | B34: =IFERROR(__xludf.DUMMYFUNCTION("""COMPUTED_VALUE"""),"(개_5)민정원9707") -> (개_5)민정원9707
A35: STU-0035 | B35: =IFERROR(__xludf.DUMMYFUNCTION("""COMPUTED_VALUE"""),"(개_5)박상현0208") -> (개_5)박상현0208
A36: STU-0036 | B36: =IFERROR(__xludf.DUMMYFUNCTION("""COMPUTED_VALUE"""),"(개_5)박시우7232") -> (개_5)박시우7232
A37: STU-0037 | B37: =IFERROR(__xludf.DUMMYFUNCTION("""COMPUTED_VALUE"""),"(개_5)방승수0714") -> (개_5)방승수0714
A38: STU-0038 | B38: =IFERROR(__xludf.DUMMYFUNCTION("""COMPUTED_VALUE"""),"(개_5)서은후1353") -> (개_5)서은후1353
A39: STU-0039 | B39: =IFERROR(__xludf.DUMMYFUNCTION("""COMPUTED_VALUE"""),"(개_5)이한결0479") -> (개_5)이한결0479
A40: STU-0040 | B40: =IFERROR(__xludf.DUMMYFUNCTION("""COMPUTED_VALUE"""),"(개_5)임건우5242") -> (개_5)임건우5242
...

Sheet 개별회수입력
A1: 요청ID | B1: 회수일 | C1: 학생명 | D1: 회수반 | E1: 회수장소 | F1: 수량 | G1: 회수사유 | H1: 담당자 | I1: 메모 | J1: 원배부일
A2: c8155e2b | B2: 46112 | C2: (5)강연웅2804 | D2: (목) 301호 생명D 강원휘(13시20분) | E2: 창고 | F2: 1 | G2: 오배부회수 | H2: 김지유 | J2: 46099
A3: 232eb27f | B3: 46114 | C3: (5)강연웅2804 | D3: 국매깨 2-5 | E3: 4층지원실 | F3: 1 | G3: 여분회수 | H3: 엄선훈 | J3: 46114
A4: 90677779 | B4: 46114 | C4: 권민서2837 | D4: 국매깨 2-6 | E4: 창고 | F4: 1 | G4: 여분회수 | H4: 김지유
A5: 16c4bfe6 | B5: 46121 | C5: 엄선훈 | D5: TEST 교재1 | E5: 창고 | G5: 1 | H5: 오배부회수 | I5: 엄선훈 | K5: 46121
A6: be112175 | B6: 46121 | C6: (5)강연웅2804 | D6: (강원휘) 생명과학 | E6: 창고 | F6: 1 | G6: 오배부회수 | H6: 김지유 | K6: 46121

Sheet 일괄회수입력
A1: 요청ID | B1: 회수일 | C1: 배부일 | D1: 반명 | E1: 회수장소 | F1: 학생당수량 | G1: 총대상학생수 | H1: 총회수수량 | I1: 실행상태 | J1: 담당자 | K1: 메모
A2: 246479f2 | B2: 46119 | C2: 46119 | D2: TEST 교재1 | E2: 창고 | F2: 1 | G2: 4 | H2: 4 | J2: 엄선훈
A3: f8727ad7 | B3: 46121 | C3: 46121 | D3: TEST 교재1 | E3: 창고 | G3: 1 | H3: 5 | I3: 5 | K3: 엄선훈
A4: 50afa2ed | B4: 46126 | C4: 46126 | D4: (강성욱) 사회문화 | E4: 창고 | F4: 1 | G4: 0 | H4: 0 | J4: 김지유
A5: 9accf211 | B5: 46126 | C5: 46126 | D5: (강성욱) 정치와 법 | E5: 창고 | F5: 1 | G5: 0 | H5: 0 | J5: 김지유

Sheet 회수로그
A1: 회수로그ID | B1: 회수일 | C1: 원배부일 | D1: 학생명 | E1: 반명 | F1: 회수방식 | G1: 회수장소 | H1: 수량 | I1: 회수사유 | J1: 담당자 | K1: 일괄요청ID | L1: 원배부로그ID
A2: b92c69fd | B2: 46119 | C2: 46119 | D2: 엄선훈 | E2: TEST 교재1 | F2: 일괄 | G2: 창고 | H2: 1 | I2: 일괄회수 | J2: 엄선훈 | K2: 246479f2 | L2: 56aa93e3
A3: a61d9e94 | B3: 46119 | C3: 46119 | D3: 박상언 | E3: TEST 교재1 | F3: 일괄 | G3: 창고 | H3: 1 | I3: 일괄회수 | J3: 엄선훈 | K3: 246479f2 | L3: 61cba809
A4: 0a60c867 | B4: 46119 | C4: 46119 | D4: 이혜진 | E4: TEST 교재1 | F4: 일괄 | G4: 창고 | H4: 1 | I4: 일괄회수 | J4: 엄선훈 | K4: 246479f2 | L4: 279d00bc
A5: 07d1d615 | B5: 46119 | C5: 46119 | D5: 김한솔 | E5: TEST 교재1 | F5: 일괄 | G5: 창고 | H5: 1 | I5: 일괄회수 | J5: 엄선훈 | K5: 246479f2 | L5: a6b6e50c
A6: 7efc5dea | B6: 46121 | C6: 46121 | D6: 엄선훈 | E6: TEST 교재1 | G6: 개별 | H6: 창고 | I6: 1 | J6: 오배부회수 | K6: 엄선훈
A7: e5fa72fa | B7: 46121 | C7: 46121 | D7: 엄선훈 | E7: TEST 교재1 | G7: 일괄 | H7: 창고 | I7: 1 | J7: 일괄회수 | K7: 엄선훈 | L7: f8727ad7 | M7: df5f5d83
A8: 74a2cecb | B8: 46121 | C8: 46121 | D8: 엄선훈 | E8: TEST 교재1 | G8: 일괄 | H8: 창고 | I8: 1 | J8: 일괄회수 | K8: 엄선훈 | L8: f8727ad7 | M8: cc89bba0
A9: b6707ded | B9: 46121 | C9: 46121 | D9: 박상언 | E9: TEST 교재1 | G9: 일괄 | H9: 창고 | I9: 1 | J9: 일괄회수 | K9: 엄선훈 | L9: f8727ad7 | M9: b69ba0d4
A10: 5c9ef1ef | B10: 46121 | C10: 46121 | D10: 이혜진 | E10: TEST 교재1 | G10: 일괄 | H10: 창고 | I10: 1 | J10: 일괄회수 | K10: 엄선훈 | L10: f8727ad7 | M10: 5f37b8d2
A11: f3fdebb5 | B11: 46121 | C11: 46121 | D11: 김한솔 | E11: TEST 교재1 | G11: 일괄 | H11: 창고 | I11: 1 | J11: 일괄회수 | K11: 엄선훈 | L11: f8727ad7 | M11: 81a39261
A12: daa8cef9 | B12: 46121 | D12: (5)강연웅2804 | E12: (강원휘) 생명과학 | F12: 개별 | G12: 창고 | H12: 1 | I12: 오배부회수 | J12: 김지유

Sheet 배부로그
A1: 로그ID | B1: 배부일 | C1: 학생명 | D1: 반명 | E1: 배부방식 | F1: 배부장소 | G1: 수량 | H1: 특이사항여부 | I1: 특이사항유형 | J1: 특이사항내용 | K1: 담당자 | L1: 배부상태 | M1: 회수일
A2: b2491d86 | B2: 46114 | C2: 김지유 | D2: 수매깨 김지유 테스트 | E2: 일괄 | F2: 창고 | G2: 1 | H2: FALSE | L2: 배부
A3: cb421782 | B3: 46114 | C3: 김대열 | D3: 수매깨 김지유 테스트 | E3: 일괄 | F3: 창고 | G3: 1 | H3: FALSE | L3: 배부
A4: ff09e0a1 | B4: 46114 | C4: 엄선훈 | D4: 수매깨 김지유 테스트 | E4: 일괄 | F4: 창고 | G4: 1 | H4: FALSE | L4: 배부
A5: c9f127bf | B5: 46115 | C5: 황수현6530 | D5: 301 전종현 수2 | E5: 일괄 | F5: 창고 | G5: 1 | H5: FALSE | L5: 배부
A6: 5a67b2b5 | B6: 46115 | C6: 황수현6530 | D6: 301 전종현 수2 | E6: 개별 | F6: 창고 | G6: 1 | H6: TRUE | I6: 기타 | J6: 신규 | L6: 배부
A7: e5437031 | B7: 46115 | C7: 황수현6530 | D7: 세타 수2 | E7: 개별 | F7: 창고 | G7: 1 | H7: TRUE | I7: 기타 | J7: 신규 | L7: 배부
A8: a0fcbde6 | B8: 46115 | C8: 황성준4580 | D8: 이민호A 301 | E8: 일괄 | F8: 창고 | G8: 1 | H8: FALSE | L8: 배부
A9: 0a63c73f | B9: 46115 | C9: 황수현6530 | D9: 이민호A 301 | E9: 일괄 | F9: 창고 | G9: 1 | H9: FALSE | L9: 배부
A10: db555315 | B10: 46115 | C10: 황시은2437 | D10: 이민호A 301 | E10: 일괄 | F10: 창고 | G10: 1 | H10: FALSE | L10: 배부
A11: cb67d984 | B11: 46115 | C11: 황준서0113 | D11: 이민호A 301 | E11: 일괄 | F11: 창고 | G11: 1 | H11: FALSE | L11: 배부
A12: f0d50ff3 | B12: 46115 | C12: 김지유 | D12: 수매깨 김지유 테스트 | E12: 개별 | G12: 1 | H12: TRUE | I12: 기타 | J12: 테스트 | L12: 배부
A13: b3676c5a | B13: 46115 | C13: 김지유 | D13: 국매깨 김지유 테스트 | E13: 개별 | F13: 창고 | G13: 1 | H13: TRUE | I13: 기타 | J13: 테스트 | L13: 배부
A14: d647332e | B14: 46115 | C14: 박상언 | D14: 국매깨2-4 박상언 테스트 | E14: 개별 | F14: 8층지원실 | G14: 1 | H14: TRUE | I14: 기타 | J14: 입학 | L14: 배부
A15: 152302fd | B15: 46115 | C15: 박상언 | D15: 국어1 박상언 테스트 | E15: 개별 | F15: 창고 | G15: 2 | H15: TRUE | I15: 기타 | J15: 테스트 | L15: 배부
A16: 6ab2bf4a | B16: 46115 | C16: 박상언 | D16: 사회문화1 박상언 테스트 | E16: 개별 | F16: 창고 | G16: 1 | H16: TRUE | I16: 기타 | J16: 테스트 | L16: 배부
A17: 82e3516f | B17: 46115 | C17: 박상언 | D17: 수학1 박상언 테스트 | E17: 개별 | F17: 창고 | G17: 1 | H17: TRUE | I17: 기타 | J17: 테스트 | L17: 배부
A18: 6f8a363a | B18: 46115 | C18: (5)강유찬8685 | D18: 정규(수)701A 영어 김희준 | E18: 개별 | F18: 창고 | G18: 1 | H18: TRUE | I18: 기타 | J18: 신규 | L18: 배부
A19: 11bf6391 | B19: 46116 | C19: 조상혁0315 | D19: (국어선택) 화법과작문 | E19: 개별 | F19: 창고 | G19: 1 | H19: TRUE | I19: 기타 | J19: 신규 | L19: 배부
A20: 1bd4454b | B20: 46116 | C20: 조상혁0315 | D20: (김학림전종현) 쎄타_미적E수업 | E20: 개별 | F20: 창고 | G20: 1 | H20: TRUE | I20: 기타 | J20: 신규 | L20: 배부
A21: 19bd47d3 | B21: 46116 | C21: 조상혁0315 | D21: (국어선택) 화법과작문 | E21: 개별 | F21: 창고 | G21: 1 | H21: TRUE | I21: 기타 | J21: 신규 | L21: 배부
A22: 088a7c57 | B22: 46116 | C22: 조상혁0315 | D22: (김학림전종현) 쎄타_미적E수업 | E22: 개별 | F22: 창고 | G22: 1 | H22: TRUE | I22: 기타 | J22: 신규 | L22: 배부
A23: 9137d696 | B23: 46116 | C23: 조상혁0315 | D23: (김학림전종현) 쎄타_미적E피드백 | E23: 개별 | F23: 창고 | G23: 1 | H23: TRUE | I23: 기타 | J23: 신규 | L23: 배부
A24: bf0b090b | B24: 46116 | C24: 조상혁0315 | D24: (김학림전종현) 쎄타_수2E수업 | E24: 개별 | F24: 창고 | G24: 1 | H24: TRUE | I24: 기타 | J24: 신규 | L24: 배부
... A157: a09c4d36 | B157: 46118 | C157: (아)황예나0608 | D157: (진명화) 에센스_확통(피드백) | E157: 개별 | F157: 창고 | G157: 1 | H157: TRUE | I157: 기타 | J157: 신규 | L157: 배부
A158: db022754 | B158: 46118 | C158: (5)강연웅2804 | D158: (국매깨) 9주차 | E158: 일괄 | F158: 창고 | G158: 1 | H158: FALSE | L158: 배부
A159: 9036712d | B159: 46118 | C159: (5)강유찬8685 | D159: (국매깨) 9주차 | E159: 일괄 | F159: 창고 | G159: 1 | H159: FALSE | L159: 배부
A160: 4d39a5c7 | B160: 46118 | C160: (5)고강민8799 | D160: (국매깨) 9주차 | E160: 일괄 | F160: 창고 | G160: 1 | H160: FALSE | L160: 배부
A161: ae80784f | B161: 46118 | C161: (5)김준수3824 | D161: (국매깨) 9주차 | E161: 일괄 | F161: 창고 | G161: 1 | H161: FALSE | L161: 배부
A162: 5ca92be1 | B162: 46118 | C162: (5)김진혁7053 | D162: (국매깨) 9주차 | E162: 일괄 | F162: 창고 | G162: 1 | H162: FALSE | L162: 배부
A163: 29b9737d | B163: 46118 | C163: (5)문혁기2222 | D163: (국매깨) 9주차 | E163: 일괄 | F163: 창고 | G163: 1 | H163: FALSE | L163: 배부
A164: f3b88994 | B164: 46118 | C164: (5)박경동8420 | D164: (국매깨) 9주차 | E164: 일괄 | F164: 창고 | G164: 1 | H164: FALSE | L164: 배부
A165: 7725b743 | B165: 46118 | C165: (5)방준혁8763 | D165: (국매깨) 9주차 | E165: 일괄 | F165: 창고 | G165: 1 | H165: FALSE | L165: 배부
A166: 04d3d2d0 | B166: 46118 | C166: (5)손찬우7814 | D166: (국매깨) 9주차 | E166: 일괄 | F166: 창고 | G166: 1 | H166: FALSE | L166: 배부
A167: bc81ae4e | B167: 46118 | C167: (5)오승민8884 | D167: (국매깨) 9주차 | E167: 일괄 | F167: 창고 | G167: 1 | H167: FALSE | L167: 배부
A168: 2ae1f011 | B168: 46118 | C168: (5)유민재7079 | D168: (국매깨) 9주차 | E168: 일괄 | F168: 창고 | G168: 1 | H168: FALSE | L168: 배부
A169: c92f2faf | B169: 46118 | C169: (5)윤태웅1592 | D169: (국매깨) 9주차 | E169: 일괄 | F169: 창고 | G169: 1 | H169: FALSE | L169: 배부
... A1471: 5fed191e | B1471: 46118 | C1471: 황성준4580 | D1471: (수매깨7주차) T | E1471: 일괄 | F1471: 창고 | G1471: 1 | H1471: FALSE | L1471: 배부
A1472: 6d824add | B1472: 46118 | C1472: 남유주5622 | D1472: (영매깨) 1학기 | E1472: 개별 | F1472: 창고 | G1472: 1 | H1472: TRUE | I1472: 기타 | J1472: 신규 | L1472: 배부
A1473: 6086d6ac | B1473: 46118 | C1473: (아)황예나0608 | D1473: (영매깨) 1학기 | E1473: 개별 | F1473: 창고 | G1473: 1 | H1473: TRUE | I1473: 기타 | J1473: 신규 | L1473: 배부
...

Sheet 반마스터
A1: 반명 | B1: 월배부기준 | C1: 사용여부
A2: (강성욱) 사회문화 | B2: 월 | C2: Y
A3: (강성욱) 정치와 법 | B3: 월 | C3: Y
A4: (강원휘) 생명과학 | B4: 월 | C4: Y
A5: (고낙기) 화학 | B5: 월 | C5: Y
A6: (국어선택) 언어와매체 | B6: 월 | C6: Y
A7: (국어선택) 화법과작문 | B7: 월 | C7: Y
A8: (김종훈) 국어다지기_독서1 | B8: 월 | C8: Y
A9: (김종훈) 국어다지기_문학1 | B9: 월 | C9: Y
A10: (김춘근김희준) pop 1 | B10: 월 | C10: Y
A11: (김춘근김희준) syntax 1 | B11: 월 | C11: Y
A12: (김학림전종현) 쎄타_미적E수업 | B12: 월 | C12: Y
... A86: (지종규) LIP_문법구문 | B86: 월 | C86: Y
B87: 월 | C87: Y
B88: 월 | C88: Y
B89: 월 | C89: Y
B90: 월 | C90: Y
B91: 월 | C91: Y
B92: 월 | C92: Y
B93: 월 | C93: Y
B94: 월 | C94: Y
B95: 월 | C95: Y
B96: 월 | C96: Y
B97: 월 | C97: Y
B98: 월 | C98: Y
... B117: 주 | C117: Y

Sheet 반별학생명단
A1: 반명 | B1: 학생명
A2: (목) 301호 생명D 강원휘(13시20분) | B2: (5)강연웅2804
A3: (목) 501호 언매 김종훈(08시) | B3: (5)강연웅2804
A4: (화) 303호 지학D 이병훈(08시) | B4: (5)강연웅2804
A5: 정규(수)802B 국어 김종훈 | B5: (5)강연웅2804
A6: 정규(월금)801B 미적 전종현(수매Q) | B6: (5)강연웅2804
A7: 정규(토)901A 영어 김희준 | B7: (5)강연웅2804
A8: 국매깨 2-5 | B8: (5)강연웅2804
A9: 수매깨 Q 1-1 | B9: (5)강연웅2804
A10: (목) 702호 화작 조영신(13시20분) | B10: (5)강유찬8685
A11: (목) 별관지하 세지A 이승국(08시) | B11: (5)강유찬8685
A12: (화) 별관302호 사문B 강성욱(13시20분) | B12: (5)강유찬8685
... A4694: TEST 교재1 | B4694: 엄선훈

Sheet 학생반배정
A1: 배정ID | B1: 학생명 | C1: 반명 | D1: 상태 | E1: 시작일 | F1: 종료일 | G1: 비고
A2: {=IF(B2:B11618<>"","BA-"&TEXT(ROW(B2:B11618)-1,"0000"),"")} -> BA-0001 | B2: (5)강연웅2804 | C2: (수매깨7주차) Q | D2: 재원 | E2: 46113 | F2: 46171
A3: BA-0002 | B3: (5)강연웅2804 | C3: (영매깨) 1학기 | D3: 재원 | E3: 46113 | F3: 46171
A4: BA-0003 | B4: (5)강연웅2804 | C4: (이병훈) 지구과학 | D4: 재원 | E4: 46113 | F4: 46171
A5: BA-0004 | B5: (5)강연웅2804 | C5: (김학림전종현) 쎄타_수2E피드백 | D5: 재원 | E5: 46113 | F5: 46171
A6: BA-0005 | B6: (5)강연웅2804 | C6: (김학림전종현) 쎄타_수2E수업 | D6: 재원 | E6: 46113 | F6: 46171
A7: BA-0006 | B7: (5)강연웅2804 | C7: (김학림전종현) 쎄타_미적E피드백 | D7: 재원 | E7: 46113 | F7: 46171
A8: BA-0007 | B8: (5)강연웅2804 | C8: (김학림전종현) 쎄타_미적E수업 | D8: 재원 | E8: 46113 | F8: 46171
A9: BA-0008 | B9: (5)강연웅2804 | C9: (김춘근김희준) syntax 2 | D9: 재원 | E9: 46113 | F9: 46171
A10: BA-0009 | B10: (5)강연웅2804 | C10: (김춘근김희준) pop 2 | D10: 재원 | E10: 46113 | F10: 46171
A11: BA-0010 | B11: (5)강연웅2804 | C11: (김종훈) 국어다지기_문학2 | D11: 재원 | E11: 46113 | F11: 46171
A12: BA-0011 | B12: (5)강연웅2804 | C12: (김종훈) 국어다지기_독서2 | D12: 재원 | E12: 46113 | F12: 46171
A13: BA-0012 | B13: (5)강연웅2804 | C13: (국어선택) 언어와매체 | D13: 재원 | E13: 46113 | F13: 46171
A14: BA-0013 | B14: (5)강연웅2804 | C14: (국매깨) 9주차 | D14: 재원 | E14: 46113 | F14: 46171
... A10618: BA-10617 | B10618: (아)김다은5516 | C10618: (국매깨) 10주차 | D10618: 재원 | E10618: 46123 | F10618: 46171

Sheet 학생조회
A1: 학생 배부 이력 조회 | L1: =IFERROR(__xludf.DUMMYFUNCTION("SORT(UNIQUE(FILTER('배부로그'!C2:C1667,'배부로그'!C2:C1667<>"""",'배부로그'!L2:L1667=""배부"")))"),"(5)강연웅2804") -> (5)강연웅2804
L2: =IFERROR(__xludf.DUMMYFUNCTION("""COMPUTED_VALUE"""),"(5)강유찬8685") -> (5)강유찬8685
A3: 학생명 | B3: 엄선훈 | C3: 사용법 | L3: =IFERROR(__xludf.DUMMYFUNCTION("""COMPUTED_VALUE"""),"(5)고강민8799") -> (5)고강민8799
A4: 기준일 | B4: 46125 | C4: 학생명과 기준일을 입력하면 그 날짜까지 배부받은 교재가 아래에 표시됩니다. | L4: =IFERROR(__xludf.DUMMYFUNCTION("""COMPUTED_VALUE"""),"(5)김준수3824") -> (5)김준수3824
L5: =IFERROR(__xludf.DUMMYFUNCTION("""COMPUTED_VALUE"""),"(5)김진혁7053") -> (5)김진혁7053
A6: 배부일 | B6: 반명 | C6: 배부장소 | D6: 배부방식 | E6: 수량 | F6: 특이사항 | L6: =IFERROR(__xludf.DUMMYFUNCTION("""COMPUTED_VALUE"""),"(5)문혁기2222") -> (5)문혁기2222
A7: =IFERROR(__xludf.DUMMYFUNCTION("IF( OR($B$3="""",$B$4=""""), ""해당 내역 없음"", IFERROR( FILTER( { TEXT('배부로그'!B2:B1667,""yyyy-mm-dd""), '배부로그'!D2:D1667, '배부로그'!F2:F1667, '배부로그'!E2:E1667, '배부로그'!G2:G1667, IF( ('배부로그'!H"&"2:H1667=""Y"")+('배부로그'!H2:H1667=TRUE), IF( '배부로그'!I2:I1667<>"""", '배부로그'!I2:I1667 & IF('배부로그'!J2:J1667<>"""","" / ""&'배부로그'!J2:J1667,""""), '배부로그'!J2:J1667 ), """" ) }, "&"TRIM('배부로그'!C2:C1667)=TRIM($B$3), INT('배부로그'!B2:B1667)<=INT($B$4) ), ""해당 내역 없음"" ) )"),"2026-04-02") -> 2026-04-02 | B7: =IFERROR(__xludf.DUMMYFUNCTION("""COMPUTED_VALUE"""),"수매깨 김지유 테스트") -> 수매깨 김지유 테스트 | C7: =IFERROR(__xludf.DUMMYFUNCTION("""COMPUTED_VALUE"""),"창고") -> 창고 | D7: =IFERROR(__xludf.DUMMYFUNCTION("""COMPUTED_VALUE"""),"일괄") -> 일괄 | E7: =IFERROR(__xludf.DUMMYFUNCTION("""COMPUTED_VALUE"""),1.0) -> 1 | F7: =IFERROR(__xludf.DUMMYFUNCTION("""COMPUTED_VALUE"""),"") | L7: =IFERROR(__xludf.DUMMYFUNCTION("""COMPUTED_VALUE"""),"(5)박건영5869") -> (5)박건영5869
A8: =IFERROR(__xludf.DUMMYFUNCTION("""COMPUTED_VALUE"""),"2026-04-07") -> 2026-04-07 | B8: =IFERROR(__xludf.DUMMYFUNCTION("""COMPUTED_VALUE"""),"TEST 교재1") -> TEST 교재1 | C8: =IFERROR(__xludf.DUMMYFUNCTION("""COMPUTED_VALUE"""),"창고") -> 창고 | D8: =IFERROR(__xludf.DUMMYFUNCTION("""COMPUTED_VALUE"""),"일괄") -> 일괄 | E8: =IFERROR(__xludf.DUMMYFUNCTION("""COMPUTED_VALUE"""),1.0) -> 1 | F8: =IFERROR(__xludf.DUMMYFUNCTION("""COMPUTED_VALUE"""),"") | L8: =IFERROR(__xludf.DUMMYFUNCTION("""COMPUTED_VALUE"""),"(5)박경동8420") -> (5)박경동8420
A9: =IFERROR(__xludf.DUMMYFUNCTION("""COMPUTED_VALUE"""),"2026-04-09") -> 2026-04-09 | B9: =IFERROR(__xludf.DUMMYFUNCTION("""COMPUTED_VALUE"""),"TEST 교재1") -> TEST 교재1 | C9: =IFERROR(__xludf.DUMMYFUNCTION("""COMPUTED_VALUE"""),"창고") -> 창고 | D9: =IFERROR(__xludf.DUMMYFUNCTION("""COMPUTED_VALUE"""),"개별") -> 개별 | E9: =IFERROR(__xludf.DUMMYFUNCTION("""COMPUTED_VALUE"""),1.0) -> 1 | F9: =IFERROR(__xludf.DUMMYFUNCTION("""COMPUTED_VALUE"""),"신규") -> 신규 | L9: =IFERROR(__xludf.DUMMYFUNCTION("""COMPUTED_VALUE"""),"(5)방준혁8763") -> (5)방준혁8763
A10: =IFERROR(__xludf.DUMMYFUNCTION("""COMPUTED_VALUE"""),"2026-04-09") -> 2026-04-09 | B10: =IFERROR(__xludf.DUMMYFUNCTION("""COMPUTED_VALUE"""),"TEST 교재1") -> TEST 교재1 | C10: =IFERROR(__xludf.DUMMYFUNCTION("""COMPUTED_VALUE"""),"창고") -> 창고 | D10: =IFERROR(__xludf.DUMMYFUNCTION("""COMPUTED_VALUE"""),"일괄") -> 일괄 | E10: =IFERROR(__xludf.DUMMYFUNCTION("""COMPUTED_VALUE"""),1.0) -> 1 | F10: =IFERROR(__xludf.DUMMYFUNCTION("""COMPUTED_VALUE"""),"") | L10: =IFERROR(__xludf.DUMMYFUNCTION("""COMPUTED_VALUE"""),"(5)손찬우7814") -> (5)손찬우7814
A11: =IFERROR(__xludf.DUMMYFUNCTION("""COMPUTED_VALUE"""),"2026-04-13") -> 2026-04-13 | B11: =IFERROR(__xludf.DUMMYFUNCTION("""COMPUTED_VALUE"""),"TEST 교재1") -> TEST 교재1 | C11: =IFERROR(__xludf.DUMMYFUNCTION("""COMPUTED_VALUE"""),"창고") -> 창고 | D11: =IFERROR(__xludf.DUMMYFUNCTION("""COMPUTED_VALUE"""),"개별") -> 개별 | E11: =IFERROR(__xludf.DUMMYFUNCTION("""COMPUTED_VALUE"""),1.0) -> 1 | F11: =IFERROR(__xludf.DUMMYFUNCTION("""COMPUTED_VALUE"""),"분실") -> 분실 | L11: =IFERROR(__xludf.DUMMYFUNCTION("""COMPUTED_VALUE"""),"(5)오승민8884") -> (5)오승민8884
L12: =IFERROR(__xludf.DUMMYFUNCTION("""COMPUTED_VALUE"""),"(5)유민재7079") -> (5)유민재7079
L13: =IFERROR(__xludf.DUMMYFUNCTION("""COMPUTED_VALUE"""),"(5)윤태웅1592") -> (5)윤태웅1592
L14: =IFERROR(__xludf.DUMMYFUNCTION("""COMPUTED_VALUE"""),"(5)이민욱7522") -> (5)이민욱7522
L15: =IFERROR(__xludf.DUMMYFUNCTION("""COMPUTED_VALUE"""),"(5)이영욱6966") -> (5)이영욱6966
L16: =IFERROR(__xludf.DUMMYFUNCTION("""COMPUTED_VALUE"""),"(5)이재국9609") -> (5)이재국9609
L17: =IFERROR(__xludf.DUMMYFUNCTION("""COMPUTED_VALUE"""),"(5)조준범0784") -> (5)조준범0784
L18: =IFERROR(__xludf.DUMMYFUNCTION("""COMPUTED_VALUE"""),"(5)지무경1270") -> (5)지무경1270
L19: =IFERROR(__xludf.DUMMYFUNCTION("""COMPUTED_VALUE"""),"(5)최민준4523") -> (5)최민준4523
L20: =IFERROR(__xludf.DUMMYFUNCTION("""COMPUTED_VALUE"""),"(5)하시원2339") -> (5)하시원2339
L21: =IFERROR(__xludf.DUMMYFUNCTION("""COMPUTED_VALUE"""),"(강)기영윤7318") -> (강)기영윤7318
L22: =IFERROR(__xludf.DUMMYFUNCTION("""COMPUTED_VALUE"""),"(강)김도형7747") -> (강)김도형7747
L23: =IFERROR(__xludf.DUMMYFUNCTION("""COMPUTED_VALUE"""),"(강)김민건8182") -> (강)김민건8182
L24: =IFERROR(__xludf.DUMMYFUNCTION("""COMPUTED_VALUE"""),"(강)김수홍7778") -> (강)김수홍7778
L25: =IFERROR(__xludf.DUMMYFUNCTION("""COMPUTED_VALUE"""),"(강)민준혁9223") -> (강)민준혁9223
L26: =IFERROR(__xludf.DUMMYFUNCTION("""COMPUTED_VALUE"""),"(강)박성효3234") -> (강)박성효3234
L27: =IFERROR(__xludf.DUMMYFUNCTION("""COMPUTED_VALUE"""),"(강)박주석8032") -> (강)박주석8032
L28: =IFERROR(__xludf.DUMMYFUNCTION("""COMPUTED_VALUE"""),"(강)왕효준2880") -> (강)왕효준2880
L29: =IFERROR(__xludf.DUMMYFUNCTION("""COMPUTED_VALUE"""),"(강)이도현1102") -> (강)이도현1102
L30: =IFERROR(__xludf.DUMMYFUNCTION("""COMPUTED_VALUE"""),"(강)이동건5693") -> (강)이동건5693
L31: =IFERROR(__xludf.DUMMYFUNCTION("""COMPUTED_VALUE"""),"(강)장윤건7351") -> (강)장윤건7351
L32: =IFERROR(__xludf.DUMMYFUNCTION("""COMPUTED_VALUE"""),"(개_5)김민준5243") -> (개_5)김민준5243
L33: =IFERROR(__xludf.DUMMYFUNCTION("""COMPUTED_VALUE"""),"(개_5)민정원9707") -> (개_5)민정원9707
L34: =IFERROR(__xludf.DUMMYFUNCTION("""COMPUTED_VALUE"""),"(개_5)박상현0208") -> (개_5)박상현0208
L35: =IFERROR(__xludf.DUMMYFUNCTION("""COMPUTED_VALUE"""),"(개_5)박시우7232") -> (개_5)박시우7232
L36: =IFERROR(__xludf.DUMMYFUNCTION("""COMPUTED_VALUE"""),"(개_5)방승수0714") -> (개_5)방승수0714
L37: =IFERROR(__xludf.DUMMYFUNCTION("""COMPUTED_VALUE"""),"(개_5)서은후1353") -> (개_5)서은후1353
L38: =IFERROR(__xludf.DUMMYFUNCTION("""COMPUTED_VALUE"""),"(개_5)양인국1316") -> (개_5)양인국1316
L39: =IFERROR(__xludf.DUMMYFUNCTION("""COMPUTED_VALUE"""),"(개_5)이한결0479") -> (개_5)이한결0479
L40: =IFERROR(__xludf.DUMMYFUNCTION("""COMPUTED_VALUE"""),"(개_5)임건우5242") -> (개_5)임건우5242
...

Sheet 교재재고
A1: 5 | B1: 반명 | C1: 초기재고_창고 | D1: 초기재고_4층지원실 | E1: 초기재고_8층지원실 | F1: 1차재고_창고 | G1: 1차재고_4층지원실 | H1: 1차재고_8층지원실 | I1: 2차재고_창고 | J1: 2차재고_4층지원실 | K1: 2차재고_8층지원실 | L1: 3차재고_창고 | M1: 3차재고_4층지원실 | N1: 3차재고_8층지원실 | O1: 4차재고_창고 | P1: 4차재고_4층지원실 | Q1: 4차재고_8층지원실 | R1: 5차재고_창고 | S1: 5차재고_4층지원실 | T1: 5차재고_8층지원실 | U1: 비고
A2: STK-0001 | B2: (강성욱) 사회문화 | C2: 11
A3: STK-0002 | B3: (강성욱) 정치와 법 | C3: 2
A4: STK-0003 | B4: (강원휘) 생명과학 | C4: 25
A5: STK-0004 | B5: (고낙기) 화학 | C5: 16
A6: STK-0005 | B6: (국어선택) 언어와매체 | C6: 8 | F6: 10
A7: STK-0006 | B7: (국어선택) 화법과작문 | C7: 15 | F7: 29
A8: STK-0007 | B8: (김종훈) 국어다지기_독서2 | C8: 140
A9: STK-0008 | B9: (김종훈) 국어다지기_문학2 | C9: 140
A10: STK-0009 | B10: (김춘근김희준) pop 2 | C10: 526
A11: STK-0010 | B11: (김춘근김희준) syntax 2 | C11: 526
A12: STK-0011 | B12: (김학림전종현) 쎄타_미적E수업 | C12: 7
A13: STK-0012 | B13: (김학림전종현) 쎄타_미적E피드백 | C13: 8
A14: STK-0013 | B14: (김학림전종현) 쎄타_수2E수업 | C14: 9
A15: STK-0014 | B15: (김학림전종현) 쎄타_수2E피드백 | C15: 9
A16: STK-0015 | B16: (김학림전종현) 쎄타_수2M수업 | C16: 11 | F16: 8
A17: STK-0016 | B17: (김학림전종현) 쎄타_수2M피드백 | C17: 9 | F17: 10
A18: STK-0017 | B18: (김학림전종현) 쎄타_확통M수업 | C18: 10 | F18: 8
A19: STK-0018 | B19: (김학림전종현) 쎄타_확통M피드백 | C19: 9 | F19: 10
A20: STK-0019 | B20: (백종수) 친절한백선생_독해풀이시즌2 | C20: 242
A21: STK-0020 | B21: (백종수) 친정한백선생_문학연계시즌2 | C21: 242
A22: STK-0021 | B22: (성열상) 물리 | C22: 11
A23: STK-0022 | B23: (수매깨7주차) J | C23: 60
A24: STK-0023 | B24: (수매깨7주차) M | C24: 122
A25: STK-0024 | B25: (수매깨7주차) Q | C25: 184
A26: STK-0025 | B26: (수매깨7주차) S | C26: 132
A27: STK-0026 | B27: (수매깨7주차) T | C27: 174
A28: STK-0027 | B28: (신인섭) 동아시아사 | C28: 6
A29: STK-0028 | B29: (신인섭) 세계사 | C29: 5
A30: STK-0029 | B30: (신현철) 메멘토_미적(수업) | C30: 9 | F30: 6
A31: STK-0030 | B31: (신현철) 메멘토_미적(피드백) | C31: 9 | F31: 6
A32: STK-0031 | B32: (신현철) 메멘토_수2(수업) | C32: 19 | F32: 6
A33: STK-0032 | B33: (신현철) 메멘토_수2(피드백) | C33: 20 | F33: 6
A34: STK-0033 | B34: (신현철) 메멘토_확통(수업) | C34: 9
A35: STK-0034 | B35: (신현철) 메멘토_확통(피드백) | C35: 9
A36: STK-0035 | B36: (이민호A) 노플_미적(피드백) | C36: 6
A37: STK-0036 | B37: (이민호A) 노플_수2(피드백) | C37: 14
A38: STK-0037 | B38: (이민호A) 노플_확통(피드백) | C38: 6
A39: STK-0038 | B39: (이민호A) 인사이트_미적(수업) | C39: 6
A40: STK-0039 | B40: (이민호A) 인사이트_수2(수업) | C40: 14
...

Sheet 재고이동로그
A1: 이동ID | B1: 이동일 | C1: 반명 | D1: 출발장소 | E1: 도착장소 | F1: 수량 | G1: 담당자 | H1: 비고

Sheet 특이사항모아보기
A1: 특이사항 학생 모아보기
A3: 배부일 | B3: 학생명 | C3: 반명 | D3: 배부장소 | E3: 수량 | F3: 특이사항유형 | G3: 특이사항내용 | H3: 담당자
A4: =IFERROR(__xludf.DUMMYFUNCTION("IFERROR( FILTER( { TEXT('배부로그'!B2:B1000,""yyyy-mm-dd""), '배부로그'!C2:C1000, '배부로그'!D2:D1000, '배부로그'!F2:F1000, '배부로그'!G2:G1000, '배부로그'!I2:I1000, '배부로그'!J2:J1000, '배부로그'!K2:K1000 }, ( ('배부로그'"&"!H2:H1000=""Y"")+ ('배부로그'!H2:H1000=TRUE)+ ('배부로그'!I2:I1000<>"""")+ ('배부로그'!J2:J1000<>"""") )>0, '배부로그'!L2:L1000=""배부"" ), ""해당 내역 없음"" )"),"2026-04-03") -> 2026-04-03 | B4: =IFERROR(__xludf.DUMMYFUNCTION("""COMPUTED_VALUE"""),"황수현6530") -> 황수현6530 | C4: =IFERROR(__xludf.DUMMYFUNCTION("""COMPUTED_VALUE"""),"301 전종현 수2") -> 301 전종현 수2 | D4: =IFERROR(__xludf.DUMMYFUNCTION("""COMPUTED_VALUE"""),"창고") -> 창고 | E4: =IFERROR(__xludf.DUMMYFUNCTION("""COMPUTED_VALUE"""),1.0) -> 1 | F4: =IFERROR(__xludf.DUMMYFUNCTION("""COMPUTED_VALUE"""),"기타") -> 기타 | G4: =IFERROR(__xludf.DUMMYFUNCTION("""COMPUTED_VALUE"""),"신규") -> 신규
A5: =IFERROR(__xludf.DUMMYFUNCTION("""COMPUTED_VALUE"""),"2026-04-03") -> 2026-04-03 | B5: =IFERROR(__xludf.DUMMYFUNCTION("""COMPUTED_VALUE"""),"황수현6530") -> 황수현6530 | C5: =IFERROR(__xludf.DUMMYFUNCTION("""COMPUTED_VALUE"""),"세타 수2") -> 세타 수2 | D5: =IFERROR(__xludf.DUMMYFUNCTION("""COMPUTED_VALUE"""),"창고") -> 창고 | E5: =IFERROR(__xludf.DUMMYFUNCTION("""COMPUTED_VALUE"""),1.0) -> 1 | F5: =IFERROR(__xludf.DUMMYFUNCTION("""COMPUTED_VALUE"""),"기타") -> 기타 | G5: =IFERROR(__xludf.DUMMYFUNCTION("""COMPUTED_VALUE"""),"신규") -> 신규
A6: =IFERROR(__xludf.DUMMYFUNCTION("""COMPUTED_VALUE"""),"2026-04-03") -> 2026-04-03 | B6: =IFERROR(__xludf.DUMMYFUNCTION("""COMPUTED_VALUE"""),"김지유") -> 김지유 | C6: =IFERROR(__xludf.DUMMYFUNCTION("""COMPUTED_VALUE"""),"수매깨 김지유 테스트") -> 수매깨 김지유 테스트 | E6: =IFERROR(__xludf.DUMMYFUNCTION("""COMPUTED_VALUE"""),1.0) -> 1 | F6: =IFERROR(__xludf.DUMMYFUNCTION("""COMPUTED_VALUE"""),"기타") -> 기타 | G6: =IFERROR(__xludf.DUMMYFUNCTION("""COMPUTED_VALUE"""),"테스트") -> 테스트
A7: =IFERROR(__xludf.DUMMYFUNCTION("""COMPUTED_VALUE"""),"2026-04-03") -> 2026-04-03 | B7: =IFERROR(__xludf.DUMMYFUNCTION("""COMPUTED_VALUE"""),"김지유") -> 김지유 | C7: =IFERROR(__xludf.DUMMYFUNCTION("""COMPUTED_VALUE"""),"국매깨 김지유 테스트") -> 국매깨 김지유 테스트 | D7: =IFERROR(__xludf.DUMMYFUNCTION("""COMPUTED_VALUE"""),"창고") -> 창고 | E7: =IFERROR(__xludf.DUMMYFUNCTION("""COMPUTED_VALUE"""),1.0) -> 1 | F7: =IFERROR(__xludf.DUMMYFUNCTION("""COMPUTED_VALUE"""),"기타") -> 기타 | G7: =IFERROR(__xludf.DUMMYFUNCTION("""COMPUTED_VALUE"""),"테스트") -> 테스트
A8: =IFERROR(__xludf.DUMMYFUNCTION("""COMPUTED_VALUE"""),"2026-04-03") -> 2026-04-03 | B8: =IFERROR(__xludf.DUMMYFUNCTION("""COMPUTED_VALUE"""),"박상언") -> 박상언 | C8: =IFERROR(__xludf.DUMMYFUNCTION("""COMPUTED_VALUE"""),"국매깨2-4 박상언 테스트") -> 국매깨2-4 박상언 테스트 | D8: =IFERROR(__xludf.DUMMYFUNCTION("""COMPUTED_VALUE"""),"8층지원실") -> 8층지원실 | E8: =IFERROR(__xludf.DUMMYFUNCTION("""COMPUTED_VALUE"""),1.0) -> 1 | F8: =IFERROR(__xludf.DUMMYFUNCTION("""COMPUTED_VALUE"""),"기타") -> 기타 | G8: =IFERROR(__xludf.DUMMYFUNCTION("""COMPUTED_VALUE"""),"입학") -> 입학
A9: =IFERROR(__xludf.DUMMYFUNCTION("""COMPUTED_VALUE"""),"2026-04-03") -> 2026-04-03 | B9: =IFERROR(__xludf.DUMMYFUNCTION("""COMPUTED_VALUE"""),"박상언") -> 박상언 | C9: =IFERROR(__xludf.DUMMYFUNCTION("""COMPUTED_VALUE"""),"국어1 박상언 테스트") -> 국어1 박상언 테스트 | D9: =IFERROR(__xludf.DUMMYFUNCTION("""COMPUTED_VALUE"""),"창고") -> 창고 | E9: =IFERROR(__xludf.DUMMYFUNCTION("""COMPUTED_VALUE"""),2.0) -> 2 | F9: =IFERROR(__xludf.DUMMYFUNCTION("""COMPUTED_VALUE"""),"기타") -> 기타 | G9: =IFERROR(__xludf.DUMMYFUNCTION("""COMPUTED_VALUE"""),"테스트") -> 테스트
A10: =IFERROR(__xludf.DUMMYFUNCTION("""COMPUTED_VALUE"""),"2026-04-03") -> 2026-04-03 | B10: =IFERROR(__xludf.DUMMYFUNCTION("""COMPUTED_VALUE"""),"박상언") -> 박상언 | C10: =IFERROR(__xludf.DUMMYFUNCTION("""COMPUTED_VALUE"""),"사회문화1 박상언 테스트") -> 사회문화1 박상언 테스트 | D10: =IFERROR(__xludf.DUMMYFUNCTION("""COMPUTED_VALUE"""),"창고") -> 창고 | E10: =IFERROR(__xludf.DUMMYFUNCTION("""COMPUTED_VALUE"""),1.0) -> 1 | F10: =IFERROR(__xludf.DUMMYFUNCTION("""COMPUTED_VALUE"""),"기타") -> 기타 | G10: =IFERROR(__xludf.DUMMYFUNCTION("""COMPUTED_VALUE"""),"테스트") -> 테스트
A11: =IFERROR(__xludf.DUMMYFUNCTION("""COMPUTED_VALUE"""),"2026-04-03") -> 2026-04-03 | B11: =IFERROR(__xludf.DUMMYFUNCTION("""COMPUTED_VALUE"""),"박상언") -> 박상언 | C11: =IFERROR(__xludf.DUMMYFUNCTION("""COMPUTED_VALUE"""),"수학1 박상언 테스트") -> 수학1 박상언 테스트 | D11: =IFERROR(__xludf.DUMMYFUNCTION("""COMPUTED_VALUE"""),"창고") -> 창고 | E11: =IFERROR(__xludf.DUMMYFUNCTION("""COMPUTED_VALUE"""),1.0) -> 1 | F11: =IFERROR(__xludf.DUMMYFUNCTION("""COMPUTED_VALUE"""),"기타") -> 기타 | G11: =IFERROR(__xludf.DUMMYFUNCTION("""COMPUTED_VALUE"""),"테스트") -> 테스트
A12: =IFERROR(__xludf.DUMMYFUNCTION("""COMPUTED_VALUE"""),"2026-04-03") -> 2026-04-03 | B12: =IFERROR(__xludf.DUMMYFUNCTION("""COMPUTED_VALUE"""),"(5)강유찬8685") -> (5)강유찬8685 | C12: =IFERROR(__xludf.DUMMYFUNCTION("""COMPUTED_VALUE"""),"정규(수)701A 영어 김희준") -> 정규(수)701A 영어 김희준 | D12: =IFERROR(__xludf.DUMMYFUNCTION("""COMPUTED_VALUE"""),"창고") -> 창고 | E12: =IFERROR(__xludf.DUMMYFUNCTION("""COMPUTED_VALUE"""),1.0) -> 1 | F12: =IFERROR(__xludf.DUMMYFUNCTION("""COMPUTED_VALUE"""),"기타") -> 기타 | G12: =IFERROR(__xludf.DUMMYFUNCTION("""COMPUTED_VALUE"""),"신규") -> 신규
A13: =IFERROR(__xludf.DUMMYFUNCTION("""COMPUTED_VALUE"""),"2026-04-04") -> 2026-04-04 | B13: =IFERROR(__xludf.DUMMYFUNCTION("""COMPUTED_VALUE"""),"조상혁0315") -> 조상혁0315 | C13: =IFERROR(__xludf.DUMMYFUNCTION("""COMPUTED_VALUE"""),"(국어선택) 화법과작문") -> (국어선택) 화법과작문 | D13: =IFERROR(__xludf.DUMMYFUNCTION("""COMPUTED_VALUE"""),"창고") -> 창고 | E13: =IFERROR(__xludf.DUMMYFUNCTION("""COMPUTED_VALUE"""),1.0) -> 1 | F13: =IFERROR(__xludf.DUMMYFUNCTION("""COMPUTED_VALUE"""),"기타") -> 기타 | G13: =IFERROR(__xludf.DUMMYFUNCTION("""COMPUTED_VALUE"""),"신규") -> 신규
A14: =IFERROR(__xludf.DUMMYFUNCTION("""COMPUTED_VALUE"""),"2026-04-04") -> 2026-04-04 | B14: =IFERROR(__xludf.DUMMYFUNCTION("""COMPUTED_VALUE"""),"조상혁0315") -> 조상혁0315 | C14: =IFERROR(__xludf.DUMMYFUNCTION("""COMPUTED_VALUE"""),"(김학림전종현) 쎄타_미적E수업") -> (김학림전종현) 쎄타_미적E수업 | D14: =IFERROR(__xludf.DUMMYFUNCTION("""COMPUTED_VALUE"""),"창고") -> 창고 | E14: =IFERROR(__xludf.DUMMYFUNCTION("""COMPUTED_VALUE"""),1.0) -> 1 | F14: =IFERROR(__xludf.DUMMYFUNCTION("""COMPUTED_VALUE"""),"기타") -> 기타 | G14: =IFERROR(__xludf.DUMMYFUNCTION("""COMPUTED_VALUE"""),"신규") -> 신규
A15: =IFERROR(__xludf.DUMMYFUNCTION("""COMPUTED_VALUE"""),"2026-04-04") -> 2026-04-04 | B15: =IFERROR(__xludf.DUMMYFUNCTION("""COMPUTED_VALUE"""),"조상혁0315") -> 조상혁0315 | C15: =IFERROR(__xludf.DUMMYFUNCTION("""COMPUTED_VALUE"""),"(국어선택) 화법과작문") -> (국어선택) 화법과작문 | D15: =IFERROR(__xludf.DUMMYFUNCTION("""COMPUTED_VALUE"""),"창고") -> 창고 | E15: =IFERROR(__xludf.DUMMYFUNCTION("""COMPUTED_VALUE"""),1.0) -> 1 | F15: =IFERROR(__xludf.DUMMYFUNCTION("""COMPUTED_VALUE"""),"기타") -> 기타 | G15: =IFERROR(__xludf.DUMMYFUNCTION("""COMPUTED_VALUE"""),"신규") -> 신규
A16: =IFERROR(__xludf.DUMMYFUNCTION("""COMPUTED_VALUE"""),"2026-04-04") -> 2026-04-04 | B16: =IFERROR(__xludf.DUMMYFUNCTION("""COMPUTED_VALUE"""),"조상혁0315") -> 조상혁0315 | C16: =IFERROR(__xludf.DUMMYFUNCTION("""COMPUTED_VALUE"""),"(김학림전종현) 쎄타_미적E수업") -> (김학림전종현) 쎄타_미적E수업 | D16: =IFERROR(__xludf.DUMMYFUNCTION("""COMPUTED_VALUE"""),"창고") -> 창고 | E16: =IFERROR(__xludf.DUMMYFUNCTION("""COMPUTED_VALUE"""),1.0) -> 1 | F16: =IFERROR(__xludf.DUMMYFUNCTION("""COMPUTED_VALUE"""),"기타") -> 기타 | G16: =IFERROR(__xludf.DUMMYFUNCTION("""COMPUTED_VALUE"""),"신규") -> 신규
A17: =IFERROR(__xludf.DUMMYFUNCTION("""COMPUTED_VALUE"""),"2026-04-04") -> 2026-04-04 | B17: =IFERROR(__xludf.DUMMYFUNCTION("""COMPUTED_VALUE"""),"조상혁0315") -> 조상혁0315 | C17: =IFERROR(__xludf.DUMMYFUNCTION("""COMPUTED_VALUE"""),"(김학림전종현) 쎄타_미적E피드백") -> (김학림전종현) 쎄타_미적E피드백 | D17: =IFERROR(__xludf.DUMMYFUNCTION("""COMPUTED_VALUE"""),"창고") -> 창고 | E17: =IFERROR(__xludf.DUMMYFUNCTION("""COMPUTED_VALUE"""),1.0) -> 1 | F17: =IFERROR(__xludf.DUMMYFUNCTION("""COMPUTED_VALUE"""),"기타") -> 기타 | G17: =IFERROR(__xludf.DUMMYFUNCTION("""COMPUTED_VALUE"""),"신규") -> 신규
A18: =IFERROR(__xludf.DUMMYFUNCTION("""COMPUTED_VALUE"""),"2026-04-04") -> 2026-04-04 | B18: =IFERROR(__xludf.DUMMYFUNCTION("""COMPUTED_VALUE"""),"조상혁0315") -> 조상혁0315 | C18: =IFERROR(__xludf.DUMMYFUNCTION("""COMPUTED_VALUE"""),"(김학림전종현) 쎄타_수2E수업") -> (김학림전종현) 쎄타_수2E수업 | D18: =IFERROR(__xludf.DUMMYFUNCTION("""COMPUTED_VALUE"""),"창고") -> 창고 | E18: =IFERROR(__xludf.DUMMYFUNCTION("""COMPUTED_VALUE"""),1.0) -> 1 | F18: =IFERROR(__xludf.DUMMYFUNCTION("""COMPUTED_VALUE"""),"기타") -> 기타 | G18: =IFERROR(__xludf.DUMMYFUNCTION("""COMPUTED_VALUE"""),"신규") -> 신규
A19: =IFERROR(__xludf.DUMMYFUNCTION("""COMPUTED_VALUE"""),"2026-04-04") -> 2026-04-04 | B19: =IFERROR(__xludf.DUMMYFUNCTION("""COMPUTED_VALUE"""),"조상혁0315") -> 조상혁0315 | C19: =IFERROR(__xludf.DUMMYFUNCTION("""COMPUTED_VALUE"""),"(김학림전종현) 쎄타_수2E피드백") -> (김학림전종현) 쎄타_수2E피드백 | D19: =IFERROR(__xludf.DUMMYFUNCTION("""COMPUTED_VALUE"""),"창고") -> 창고 | E19: =IFERROR(__xludf.DUMMYFUNCTION("""COMPUTED_VALUE"""),1.0) -> 1 | F19: =IFERROR(__xludf.DUMMYFUNCTION("""COMPUTED_VALUE"""),"기타") -> 기타 | G19: =IFERROR(__xludf.DUMMYFUNCTION("""COMPUTED_VALUE"""),"신규") -> 신규
A20: =IFERROR(__xludf.DUMMYFUNCTION("""COMPUTED_VALUE"""),"2026-04-04") -> 2026-04-04 | B20: =IFERROR(__xludf.DUMMYFUNCTION("""COMPUTED_VALUE"""),"조상혁0315") -> 조상혁0315 | C20: =IFERROR(__xludf.DUMMYFUNCTION("""COMPUTED_VALUE"""),"(장진민) 생활과 윤리") -> (장진민) 생활과 윤리 | D20: =IFERROR(__xludf.DUMMYFUNCTION("""COMPUTED_VALUE"""),"창고") -> 창고 | E20: =IFERROR(__xludf.DUMMYFUNCTION("""COMPUTED_VALUE"""),1.0) -> 1 | F20: =IFERROR(__xludf.DUMMYFUNCTION("""COMPUTED_VALUE"""),"기타") -> 기타 | G20: =IFERROR(__xludf.DUMMYFUNCTION("""COMPUTED_VALUE"""),"신규") -> 신규
A21: =IFERROR(__xludf.DUMMYFUNCTION("""COMPUTED_VALUE"""),"2026-04-04") -> 2026-04-04 | B21: =IFERROR(__xludf.DUMMYFUNCTION("""COMPUTED_VALUE"""),"김진영2280") -> 김진영2280 | C21: =IFERROR(__xludf.DUMMYFUNCTION("""COMPUTED_VALUE"""),"(강성욱) 사회문화") -> (강성욱) 사회문화 | D21: =IFERROR(__xludf.DUMMYFUNCTION("""COMPUTED_VALUE"""),"창고") -> 창고 | E21: =IFERROR(__xludf.DUMMYFUNCTION("""COMPUTED_VALUE"""),1.0) -> 1 | F21: =IFERROR(__xludf.DUMMYFUNCTION("""COMPUTED_VALUE"""),"기타") -> 기타 | G21: =IFERROR(__xludf.DUMMYFUNCTION("""COMPUTED_VALUE"""),"신규") -> 신규
A22: =IFERROR(__xludf.DUMMYFUNCTION("""COMPUTED_VALUE"""),"2026-04-04") -> 2026-04-04 | B22: =IFERROR(__xludf.DUMMYFUNCTION("""COMPUTED_VALUE"""),"김진영2280") -> 김진영2280 | C22: =IFERROR(__xludf.DUMMYFUNCTION("""COMPUTED_VALUE"""),"(국어선택) 언어와매체") -> (국어선택) 언어와매체 | D22: =IFERROR(__xludf.DUMMYFUNCTION("""COMPUTED_VALUE"""),"창고") -> 창고 | E22: =IFERROR(__xludf.DUMMYFUNCTION("""COMPUTED_VALUE"""),1.0) -> 1 | F22: =IFERROR(__xludf.DUMMYFUNCTION("""COMPUTED_VALUE"""),"기타") -> 기타 | G22: =IFERROR(__xludf.DUMMYFUNCTION("""COMPUTED_VALUE"""),"신규") -> 신규
A23: =IFERROR(__xludf.DUMMYFUNCTION("""COMPUTED_VALUE"""),"2026-04-04") -> 2026-04-04 | B23: =IFERROR(__xludf.DUMMYFUNCTION("""COMPUTED_VALUE"""),"김진영2280") -> 김진영2280 | C23: =IFERROR(__xludf.DUMMYFUNCTION("""COMPUTED_VALUE"""),"(신현철) 메멘토_미적(수업)") -> (신현철) 메멘토_미적(수업) | D23: =IFERROR(__xludf.DUMMYFUNCTION("""COMPUTED_VALUE"""),"창고") -> 창고 | E23: =IFERROR(__xludf.DUMMYFUNCTION("""COMPUTED_VALUE"""),1.0) -> 1 | F23: =IFERROR(__xludf.DUMMYFUNCTION("""COMPUTED_VALUE"""),"기타") -> 기타 | G23: =IFERROR(__xludf.DUMMYFUNCTION("""COMPUTED_VALUE"""),"신규") -> 신규
A24: =IFERROR(__xludf.DUMMYFUNCTION("""COMPUTED_VALUE"""),"2026-04-04") -> 2026-04-04 | B24: =IFERROR(__xludf.DUMMYFUNCTION("""COMPUTED_VALUE"""),"김진영2280") -> 김진영2280 | C24: =IFERROR(__xludf.DUMMYFUNCTION("""COMPUTED_VALUE"""),"(신현철) 메멘토_미적(피드백)") -> (신현철) 메멘토_미적(피드백) | D24: =IFERROR(__xludf.DUMMYFUNCTION("""COMPUTED_VALUE"""),"창고") -> 창고 | E24: =IFERROR(__xludf.DUMMYFUNCTION("""COMPUTED_VALUE"""),1.0) -> 1 | F24: =IFERROR(__xludf.DUMMYFUNCTION("""COMPUTED_VALUE"""),"기타") -> 기타 | G24: =IFERROR(__xludf.DUMMYFUNCTION("""COMPUTED_VALUE"""),"신규") -> 신규
A25: =IFERROR(__xludf.DUMMYFUNCTION("""COMPUTED_VALUE"""),"2026-04-04") -> 2026-04-04 | B25: =IFERROR(__xludf.DUMMYFUNCTION("""COMPUTED_VALUE"""),"김진영2280") -> 김진영2280 | C25: =IFERROR(__xludf.DUMMYFUNCTION("""COMPUTED_VALUE"""),"(신현철) 메멘토_수2(수업)") -> (신현철) 메멘토_수2(수업) | D25: =IFERROR(__xludf.DUMMYFUNCTION("""COMPUTED_VALUE"""),"창고") -> 창고 | E25: =IFERROR(__xludf.DUMMYFUNCTION("""COMPUTED_VALUE"""),1.0) -> 1 | F25: =IFERROR(__xludf.DUMMYFUNCTION("""COMPUTED_VALUE"""),"기타") -> 기타 | G25: =IFERROR(__xludf.DUMMYFUNCTION("""COMPUTED_VALUE"""),"신규") -> 신규
A26: =IFERROR(__xludf.DUMMYFUNCTION("""COMPUTED_VALUE"""),"2026-04-04") -> 2026-04-04 | B26: =IFERROR(__xludf.DUMMYFUNCTION("""COMPUTED_VALUE"""),"김진영2280") -> 김진영2280 | C26: =IFERROR(__xludf.DUMMYFUNCTION("""COMPUTED_VALUE"""),"(신현철) 메멘토_수2(피드백)") -> (신현철) 메멘토_수2(피드백) | D26: =IFERROR(__xludf.DUMMYFUNCTION("""COMPUTED_VALUE"""),"창고") -> 창고 | E26: =IFERROR(__xludf.DUMMYFUNCTION("""COMPUTED_VALUE"""),1.0) -> 1 | F26: =IFERROR(__xludf.DUMMYFUNCTION("""COMPUTED_VALUE"""),"기타") -> 기타 | G26: =IFERROR(__xludf.DUMMYFUNCTION("""COMPUTED_VALUE"""),"신규") -> 신규
A27: =IFERROR(__xludf.DUMMYFUNCTION("""COMPUTED_VALUE"""),"2026-04-04") -> 2026-04-04 | B27: =IFERROR(__xludf.DUMMYFUNCTION("""COMPUTED_VALUE"""),"김진영2280") -> 김진영2280 | C27: =IFERROR(__xludf.DUMMYFUNCTION("""COMPUTED_VALUE"""),"(이승국) 세계지리") -> (이승국) 세계지리 | D27: =IFERROR(__xludf.DUMMYFUNCTION("""COMPUTED_VALUE"""),"창고") -> 창고 | E27: =IFERROR(__xludf.DUMMYFUNCTION("""COMPUTED_VALUE"""),1.0) -> 1 | F27: =IFERROR(__xludf.DUMMYFUNCTION("""COMPUTED_VALUE"""),"기타") -> 기타 | G27: =IFERROR(__xludf.DUMMYFUNCTION("""COMPUTED_VALUE"""),"신규") -> 신규
A28: =IFERROR(__xludf.DUMMYFUNCTION("""COMPUTED_VALUE"""),"2026-04-04") -> 2026-04-04 | B28: =IFERROR(__xludf.DUMMYFUNCTION("""COMPUTED_VALUE"""),"김서우9330") -> 김서우9330 | C28: =IFERROR(__xludf.DUMMYFUNCTION("""COMPUTED_VALUE"""),"(강원휘) 생명과학") -> (강원휘) 생명과학 | D28: =IFERROR(__xludf.DUMMYFUNCTION("""COMPUTED_VALUE"""),"창고") -> 창고 | E28: =IFERROR(__xludf.DUMMYFUNCTION("""COMPUTED_VALUE"""),1.0) -> 1 | F28: =IFERROR(__xludf.DUMMYFUNCTION("""COMPUTED_VALUE"""),"기타") -> 기타 | G28: =IFERROR(__xludf.DUMMYFUNCTION("""COMPUTED_VALUE"""),"신규") -> 신규
A29: =IFERROR(__xludf.DUMMYFUNCTION("""COMPUTED_VALUE"""),"2026-04-04") -> 2026-04-04 | B29: =IFERROR(__xludf.DUMMYFUNCTION("""COMPUTED_VALUE"""),"김서우9330") -> 김서우9330 | C29: =IFERROR(__xludf.DUMMYFUNCTION("""COMPUTED_VALUE"""),"(국어선택) 화법과작문") -> (국어선택) 화법과작문 | D29: =IFERROR(__xludf.DUMMYFUNCTION("""COMPUTED_VALUE"""),"창고") -> 창고 | E29: =IFERROR(__xludf.DUMMYFUNCTION("""COMPUTED_VALUE"""),1.0) -> 1 | F29: =IFERROR(__xludf.DUMMYFUNCTION("""COMPUTED_VALUE"""),"기타") -> 기타 | G29: =IFERROR(__xludf.DUMMYFUNCTION("""COMPUTED_VALUE"""),"신규") -> 신규
A30: =IFERROR(__xludf.DUMMYFUNCTION("""COMPUTED_VALUE"""),"2026-04-04") -> 2026-04-04 | B30: =IFERROR(__xludf.DUMMYFUNCTION("""COMPUTED_VALUE"""),"김서우9330") -> 김서우9330 | C30: =IFERROR(__xludf.DUMMYFUNCTION("""COMPUTED_VALUE"""),"(신현철) 메멘토_미적(수업)") -> (신현철) 메멘토_미적(수업) | D30: =IFERROR(__xludf.DUMMYFUNCTION("""COMPUTED_VALUE"""),"창고") -> 창고 | E30: =IFERROR(__xludf.DUMMYFUNCTION("""COMPUTED_VALUE"""),1.0) -> 1 | F30: =IFERROR(__xludf.DUMMYFUNCTION("""COMPUTED_VALUE"""),"기타") -> 기타 | G30: =IFERROR(__xludf.DUMMYFUNCTION("""COMPUTED_VALUE"""),"신규") -> 신규
A31: =IFERROR(__xludf.DUMMYFUNCTION("""COMPUTED_VALUE"""),"2026-04-04") -> 2026-04-04 | B31: =IFERROR(__xludf.DUMMYFUNCTION("""COMPUTED_VALUE"""),"김서우9330") -> 김서우9330 | C31: =IFERROR(__xludf.DUMMYFUNCTION("""COMPUTED_VALUE"""),"(신현철) 메멘토_미적(피드백)") -> (신현철) 메멘토_미적(피드백) | D31: =IFERROR(__xludf.DUMMYFUNCTION("""COMPUTED_VALUE"""),"창고") -> 창고 | E31: =IFERROR(__xludf.DUMMYFUNCTION("""COMPUTED_VALUE"""),1.0) -> 1 | F31: =IFERROR(__xludf.DUMMYFUNCTION("""COMPUTED_VALUE"""),"기타") -> 기타 | G31: =IFERROR(__xludf.DUMMYFUNCTION("""COMPUTED_VALUE"""),"신규") -> 신규
A32: =IFERROR(__xludf.DUMMYFUNCTION("""COMPUTED_VALUE"""),"2026-04-04") -> 2026-04-04 | B32: =IFERROR(__xludf.DUMMYFUNCTION("""COMPUTED_VALUE"""),"김서우9330") -> 김서우9330 | C32: =IFERROR(__xludf.DUMMYFUNCTION("""COMPUTED_VALUE"""),"(신현철) 메멘토_수2(수업)") -> (신현철) 메멘토_수2(수업) | D32: =IFERROR(__xludf.DUMMYFUNCTION("""COMPUTED_VALUE"""),"창고") -> 창고 | E32: =IFERROR(__xludf.DUMMYFUNCTION("""COMPUTED_VALUE"""),1.0) -> 1 | F32: =IFERROR(__xludf.DUMMYFUNCTION("""COMPUTED_VALUE"""),"기타") -> 기타 | G32: =IFERROR(__xludf.DUMMYFUNCTION("""COMPUTED_VALUE"""),"신규") -> 신규
A33: =IFERROR(__xludf.DUMMYFUNCTION("""COMPUTED_VALUE"""),"2026-04-04") -> 2026-04-04 | B33: =IFERROR(__xludf.DUMMYFUNCTION("""COMPUTED_VALUE"""),"김서우9330") -> 김서우9330 | C33: =IFERROR(__xludf.DUMMYFUNCTION("""COMPUTED_VALUE"""),"(신현철) 메멘토_수2(피드백)") -> (신현철) 메멘토_수2(피드백) | D33: =IFERROR(__xludf.DUMMYFUNCTION("""COMPUTED_VALUE"""),"창고") -> 창고 | E33: =IFERROR(__xludf.DUMMYFUNCTION("""COMPUTED_VALUE"""),1.0) -> 1 | F33: =IFERROR(__xludf.DUMMYFUNCTION("""COMPUTED_VALUE"""),"기타") -> 기타 | G33: =IFERROR(__xludf.DUMMYFUNCTION("""COMPUTED_VALUE"""),"신규") -> 신규
A34: =IFERROR(__xludf.DUMMYFUNCTION("""COMPUTED_VALUE"""),"2026-04-04") -> 2026-04-04 | B34: =IFERROR(__xludf.DUMMYFUNCTION("""COMPUTED_VALUE"""),"김서우9330") -> 김서우9330 | C34: =IFERROR(__xludf.DUMMYFUNCTION("""COMPUTED_VALUE"""),"(장진민) 생활과 윤리") -> (장진민) 생활과 윤리 | D34: =IFERROR(__xludf.DUMMYFUNCTION("""COMPUTED_VALUE"""),"창고") -> 창고 | E34: =IFERROR(__xludf.DUMMYFUNCTION("""COMPUTED_VALUE"""),1.0) -> 1 | F34: =IFERROR(__xludf.DUMMYFUNCTION("""COMPUTED_VALUE"""),"기타") -> 기타 | G34: =IFERROR(__xludf.DUMMYFUNCTION("""COMPUTED_VALUE"""),"신규") -> 신규
A35: =IFERROR(__xludf.DUMMYFUNCTION("""COMPUTED_VALUE"""),"2026-04-04") -> 2026-04-04 | B35: =IFERROR(__xludf.DUMMYFUNCTION("""COMPUTED_VALUE"""),"최정은9852") -> 최정은9852 | C35: =IFERROR(__xludf.DUMMYFUNCTION("""COMPUTED_VALUE"""),"(강성욱) 사회문화") -> (강성욱) 사회문화 | D35: =IFERROR(__xludf.DUMMYFUNCTION("""COMPUTED_VALUE"""),"창고") -> 창고 | E35: =IFERROR(__xludf.DUMMYFUNCTION("""COMPUTED_VALUE"""),1.0) -> 1 | F35: =IFERROR(__xludf.DUMMYFUNCTION("""COMPUTED_VALUE"""),"기타") -> 기타 | G35: =IFERROR(__xludf.DUMMYFUNCTION("""COMPUTED_VALUE"""),"신규") -> 신규
A36: =IFERROR(__xludf.DUMMYFUNCTION("""COMPUTED_VALUE"""),"2026-04-04") -> 2026-04-04 | B36: =IFERROR(__xludf.DUMMYFUNCTION("""COMPUTED_VALUE"""),"최정은9852") -> 최정은9852 | C36: =IFERROR(__xludf.DUMMYFUNCTION("""COMPUTED_VALUE"""),"(국어선택) 화법과작문") -> (국어선택) 화법과작문 | D36: =IFERROR(__xludf.DUMMYFUNCTION("""COMPUTED_VALUE"""),"창고") -> 창고 | E36: =IFERROR(__xludf.DUMMYFUNCTION("""COMPUTED_VALUE"""),1.0) -> 1 | F36: =IFERROR(__xludf.DUMMYFUNCTION("""COMPUTED_VALUE"""),"기타") -> 기타 | G36: =IFERROR(__xludf.DUMMYFUNCTION("""COMPUTED_VALUE"""),"신규") -> 신규
A37: =IFERROR(__xludf.DUMMYFUNCTION("""COMPUTED_VALUE"""),"2026-04-04") -> 2026-04-04 | B37: =IFERROR(__xludf.DUMMYFUNCTION("""COMPUTED_VALUE"""),"최정은9852") -> 최정은9852 | C37: =IFERROR(__xludf.DUMMYFUNCTION("""COMPUTED_VALUE"""),"(신현철) 메멘토_미적(수업)") -> (신현철) 메멘토_미적(수업) | D37: =IFERROR(__xludf.DUMMYFUNCTION("""COMPUTED_VALUE"""),"창고") -> 창고 | E37: =IFERROR(__xludf.DUMMYFUNCTION("""COMPUTED_VALUE"""),1.0) -> 1 | F37: =IFERROR(__xludf.DUMMYFUNCTION("""COMPUTED_VALUE"""),"기타") -> 기타 | G37: =IFERROR(__xludf.DUMMYFUNCTION("""COMPUTED_VALUE"""),"신규") -> 신규
A38: =IFERROR(__xludf.DUMMYFUNCTION("""COMPUTED_VALUE"""),"2026-04-04") -> 2026-04-04 | B38: =IFERROR(__xludf.DUMMYFUNCTION("""COMPUTED_VALUE"""),"최정은9852") -> 최정은9852 | C38: =IFERROR(__xludf.DUMMYFUNCTION("""COMPUTED_VALUE"""),"(신현철) 메멘토_미적(피드백)") -> (신현철) 메멘토_미적(피드백) | D38: =IFERROR(__xludf.DUMMYFUNCTION("""COMPUTED_VALUE"""),"창고") -> 창고 | E38: =IFERROR(__xludf.DUMMYFUNCTION("""COMPUTED_VALUE"""),1.0) -> 1 | F38: =IFERROR(__xludf.DUMMYFUNCTION("""COMPUTED_VALUE"""),"기타") -> 기타 | G38: =IFERROR(__xludf.DUMMYFUNCTION("""COMPUTED_VALUE"""),"신규") -> 신규
A39: =IFERROR(__xludf.DUMMYFUNCTION("""COMPUTED_VALUE"""),"2026-04-04") -> 2026-04-04 | B39: =IFERROR(__xludf.DUMMYFUNCTION("""COMPUTED_VALUE"""),"최정은9852") -> 최정은9852 | C39: =IFERROR(__xludf.DUMMYFUNCTION("""COMPUTED_VALUE"""),"(신현철) 메멘토_수2(수업)") -> (신현철) 메멘토_수2(수업) | D39: =IFERROR(__xludf.DUMMYFUNCTION("""COMPUTED_VALUE"""),"창고") -> 창고 | E39: =IFERROR(__xludf.DUMMYFUNCTION("""COMPUTED_VALUE"""),1.0) -> 1 | F39: =IFERROR(__xludf.DUMMYFUNCTION("""COMPUTED_VALUE"""),"기타") -> 기타 | G39: =IFERROR(__xludf.DUMMYFUNCTION("""COMPUTED_VALUE"""),"신규") -> 신규
A40: =IFERROR(__xludf.DUMMYFUNCTION("""COMPUTED_VALUE"""),"2026-04-04") -> 2026-04-04 | B40: =IFERROR(__xludf.DUMMYFUNCTION("""COMPUTED_VALUE"""),"최정은9852") -> 최정은9852 | C40: =IFERROR(__xludf.DUMMYFUNCTION("""COMPUTED_VALUE"""),"(신현철) 메멘토_수2(피드백)") -> (신현철) 메멘토_수2(피드백) | D40: =IFERROR(__xludf.DUMMYFUNCTION("""COMPUTED_VALUE"""),"창고") -> 창고 | E40: =IFERROR(__xludf.DUMMYFUNCTION("""COMPUTED_VALUE"""),1.0) -> 1 | F40: =IFERROR(__xludf.DUMMYFUNCTION("""COMPUTED_VALUE"""),"기타") -> 기타 | G40: =IFERROR(__xludf.DUMMYFUNCTION("""COMPUTED_VALUE"""),"신규") -> 신규
A41: =IFERROR(__xludf.DUMMYFUNCTION("""COMPUTED_VALUE"""),"2026-04-04") -> 2026-04-04 | B41: =IFERROR(__xludf.DUMMYFUNCTION("""COMPUTED_VALUE"""),"최정은9852") -> 최정은9852 | C41: =IFERROR(__xludf.DUMMYFUNCTION("""COMPUTED_VALUE"""),"(장병선) 지구과학") -> (장병선) 지구과학 | D41: =IFERROR(__xludf.DUMMYFUNCTION("""COMPUTED_VALUE"""),"창고") -> 창고 | E41: =IFERROR(__xludf.DUMMYFUNCTION("""COMPUTED_VALUE"""),1.0) -> 1 | F41: =IFERROR(__xludf.DUMMYFUNCTION("""COMPUTED_VALUE"""),"기타") -> 기타 | G41: =IFERROR(__xludf.DUMMYFUNCTION("""COMPUTED_VALUE"""),"신규") -> 신규
...

Sheet 전체현황판
A1: 전체 현황판 | I1: 배부 | M1: 회수 | Q1: 교재 이동 - 출고 | T1: 교재 이동 - 입고 | W1: 현재 재고
A2: 반명 | B2: 초기재고_창고 | C2: 초기재고_4층지원실 | D2: 초기재고_8층지원실 | E2: 추가재고_창고 | F2: 추가재고_4층지원실 | G2: 추가재고_8층지원실 | H2: 총입고합계 | I2: 배부_창고 | J2: 배부_4층지원실 | K2: 배부_8층지원실 | L2: 배부총합계 | M2: 회수_창고 | N2: 회수_4층지원실 | O2: 회수_8층지원실 | P2: 회수총합계 | Q2: 이동출고_창고 | R2: 이동출고_4층지원실 | S2: 이동출고_8층지원실 | T2: 이동입고_창고 | U2: 이동입고_4층지원실 | V2: 이동입고_8층지원실 | W2: 현재재고_창고 | X2: 현재재고_4층지원실 | Y2: 현재재고_8층지원실 | Z2: 현재총재고 | AA2: 재고상태
